Workbook

Sheet Karta informacyjna
A1: Informacje ogólne
A2: Imię i nazwisko
A3: Numer siedziby stada
A4: Data rozpoczęcia | B4: 45292
A5: Data zakończenia | B5: 45292
A6: Ilość bydła w stadzie
B7: Koniec poprzedniego okresu | C7: Koniec bieżącego okresu | D7: Średnia | F7: Masa ciała
A8: Krowy | D8: =(B8+C8)/2 -> 0 | F8: 425 | G8: =F8*D8 -> 0
A9: Jałówki | D9: =(B9+C9)/2 -> 0 | F9: 200 | G9: =F9*D9 -> 0
A10: Cielęta (poniżej 6 mies.) | D10: =(B10+C10)/2 -> 0 | F10: 140 | G10: =F10*D10 -> 0
A11: Byki | D11: =(B11+C11)/2 -> 0 | F11: 425 | G11: =F11*D11 -> 0
A12: Informacje dodatkowe
A13: Wydajność mleczna (roczna) | F13: Total PCU | G13: =SUM(G8:G11) -> 0
A14: Rasy bydła (krowy, jałówki) | F14: PCU – standaryzowana średnia waga zwierząt podczas leczenia wg EMA
A15: Rasy bydła (byki)

Sheet Leczenie ogólne
A1: Leczenie ogólne
J2: =SUM(J4:J265) -> 0 | M2: =SUM(M4:M265) -> 0 | N2: =SUM(N4:N265) -> 0 | O2: =SUM(O4:O265) -> 0 | Q2: Kategoria ryzyka czyli nr np.. 1
A3: Data | B3: Kategoria bydła | C3: Liczba leczonych zwierząt | D3: Sposób podania (Route) | E3: Ryzyko powstawania oporności 1-6 | F3: Antybiotyk (Product) | G3: Dawka dzienna | H3: Ilość zastrzyków (liczba podań) | I3: Rozpoznanie (Treatments) | J3: Antybiogram [0=nie; 1=tak] | K3: Ilość podana (Amount used) | L3: Jednostka (Unit) | M3: Krytyczny [0=nie; 1=tak (Critical) [0 = no; 1 = yes] | N3: Antybiotyki krytyczne [mg/PCU] (Critically Important) [mg/PCU] | O3: Zużycie antybiotyków [mg/PCU] (Antibiotic Use) [mg/PCU] | P3: Klasa EMA A-D | T3: Total Antibiotic Use [mg/PCU] | U3: Total Critically Important [mg/PCU] | W3: Total PCU
D4: =IF(K4="","",VLOOKUP(F4,Tabelle1!$A$2:$C$496,3,0)) | E4: =IF(K4="","",VLOOKUP(F4,Tabelle1!$A$2:$M$496,13,0)) | K4: =IF(F4="","",C4*G4*H4) | L4: =IF(K4="","",VLOOKUP(F4,Tabelle1!$A$2:$I$496,9,0)) | M4: =IF(K4="","",VLOOKUP(F4,Tabelle1!$A$2:$G$496,7,0)) | N4: =IF(M4>0,O4,"") | O4: =IF(K4="","",((K4*VLOOKUP(F4,Tabelle1!$A$2:$I$496,8,0))/$W$4)) | P4: =IF(K4="","",VLOOKUP(F4,Tabelle1!$A$2:$L$496,12,0)) | R4: Total mg/PCU in herd | T4: =(SUM(O4:O265)) -> 0 | U4: =SUM(N4:N265) -> 0 | W4: =U45 -> 0
D5: =IF(K5="","",VLOOKUP(F5,Tabelle1!$A$2:$C$496,3,0)) | E5: =IF(K5="","",VLOOKUP(F5,Tabelle1!$A$2:$M$496,13,0)) | K5: =IF(F5="","",C5*G5*H5) | L5: =IF(K5="","",VLOOKUP(F5,Tabelle1!$A$2:$I$496,9,0)) | M5: =IF(K5="","",VLOOKUP(F5,Tabelle1!$A$2:$G$496,7,0)) | N5: =IF(M5>0,O5,"") | O5: =IF(K5="","",((K5*VLOOKUP(F5,Tabelle1!$A$2:$I$496,8,0))/$W$4)) | P5: =IF(K5="","",VLOOKUP(F5,Tabelle1!$A$2:$L$496,12,0))
D6: =IF(K6="","",VLOOKUP(F6,Tabelle1!$A$2:$C$496,3,0)) | E6: =IF(K6="","",VLOOKUP(F6,Tabelle1!$A$2:$M$496,13,0)) | K6: =IF(F6="","",C6*G6*H6) | L6: =IF(K6="","",VLOOKUP(F6,Tabelle1!$A$2:$I$496,9,0)) | M6: =IF(K6="","",VLOOKUP(F6,Tabelle1!$A$2:$G$496,7,0)) | N6: =IF(M6>0,O6,"") | O6: =IF(K6="","",((K6*VLOOKUP(F6,Tabelle1!$A$2:$I$496,8,0))/$W$4)) | P6: =IF(K6="","",VLOOKUP(F6,Tabelle1!$A$2:$L$496,12,0))
D7: =IF(K7="","",VLOOKUP(F7,Tabelle1!$A$2:$C$496,3,0)) | E7: =IF(K7="","",VLOOKUP(F7,Tabelle1!$A$2:$M$496,13,0)) | K7: =IF(F7="","",C7*G7*H7) | L7: =IF(K7="","",VLOOKUP(F7,Tabelle1!$A$2:$I$496,9,0)) | M7: =IF(K7="","",VLOOKUP(F7,Tabelle1!$A$2:$G$496,7,0)) | N7: =IF(M7>0,O7,"") | O7: =IF(K7="","",((K7*VLOOKUP(F7,Tabelle1!$A$2:$I$496,8,0))/$W$4)) | P7: =IF(K7="","",VLOOKUP(F7,Tabelle1!$A$2:$L$496,12,0)) | R7: Route | T7: Antibiotic Use [mg/PCU] | U7: Critically Important [mg/PCU]
D8: =IF(K8="","",VLOOKUP(F8,Tabelle1!$A$2:$C$496,3,0)) | E8: =IF(K8="","",VLOOKUP(F8,Tabelle1!$A$2:$M$496,13,0)) | K8: =IF(F8="","",C9*G8*H8) | L8: =IF(K8="","",VLOOKUP(F8,Tabelle1!$A$2:$I$496,9,0)) | M8: =IF(K8="","",VLOOKUP(F8,Tabelle1!$A$2:$G$496,7,0)) | N8: =IF(M8>0,O8,"") | O8: =IF(K8="","",((K8*VLOOKUP(F8,Tabelle1!$A$2:$I$496,8,0))/$W$4)) | P8: =IF(K8="","",VLOOKUP(F8,Tabelle1!$A$2:$L$496,12,0)) | R8: Injectable | T8: =SUMIFS($O$4:$O$265,$M$4:$M$265,"0",$D$4:$D$265,R8) -> 0 | U8: =SUMIFS($O$4:$O$265,$M$4:$M$265,"1",$D$4:$D$265,R8) -> 0 | V8: Lub tu kategoria ryzyka
D9: =IF(K9="","",VLOOKUP(F9,Tabelle1!$A$2:$C$496,3,0)) | E9: =IF(K9="","",VLOOKUP(F9,Tabelle1!$A$2:$M$496,13,0)) | K9: =IF(F9="","",C10*G9*H9) | L9: =IF(K9="","",VLOOKUP(F9,Tabelle1!$A$2:$I$496,9,0)) | M9: =IF(K9="","",VLOOKUP(F9,Tabelle1!$A$2:$G$496,7,0)) | N9: =IF(M9>0,O9,"") | O9: =IF(K9="","",((K9*VLOOKUP(F9,Tabelle1!$A$2:$I$496,8,0))/$W$4)) | P9: =IF(K9="","",VLOOKUP(F9,Tabelle1!$A$2:$L$496,12,0)) | R9: Lactatingtube | T9: =SUMIFS($O$4:$O$265,$M$4:$M$265,"0",$D$4:$D$265,R9) -> 0 | U9: =SUMIFS($O$4:$O$265,$M$4:$M$265,"1",$D$4:$D$265,R9) -> 0
D10: =IF(K10="","",VLOOKUP(F10,Tabelle1!$A$2:$C$496,3,0)) | E10: =IF(K10="","",VLOOKUP(F10,Tabelle1!$A$2:$M$496,13,0)) | K10: =IF(F10="","",C11*G10*H10) | L10: =IF(K10="","",VLOOKUP(F10,Tabelle1!$A$2:$I$496,9,0)) | M10: =IF(K10="","",VLOOKUP(F10,Tabelle1!$A$2:$G$496,7,0)) | N10: =IF(M10>0,O10,"") | O10: =IF(K10="","",((K10*VLOOKUP(F10,Tabelle1!$A$2:$I$496,8,0))/$W$4)) | P10: =IF(K10="","",VLOOKUP(F10,Tabelle1!$A$2:$L$496,12,0)) | R10: Drytube | T10: =SUMIFS($O$4:$O$265,$M$4:$M$265,"0",$D$4:$D$265,R10) -> 0 | U10: =SUMIFS($O$4:$O$265,$M$4:$M$265,"1",$D$4:$D$265,R10) -> 0
D11: =IF(K11="","",VLOOKUP(F11,Tabelle1!$A$2:$C$496,3,0)) | E11: =IF(K11="","",VLOOKUP(F11,Tabelle1!$A$2:$M$496,13,0)) | K11: =IF(F11="","",C12*G11*H11) | L11: =IF(K11="","",VLOOKUP(F11,Tabelle1!$A$2:$I$496,9,0)) | M11: =IF(K11="","",VLOOKUP(F11,Tabelle1!$A$2:$G$496,7,0)) | N11: =IF(M11>0,O11,"") | O11: =IF(K11="","",((K11*VLOOKUP(F11,Tabelle1!$A$2:$I$496,8,0))/$W$4)) | P11: =IF(K11="","",VLOOKUP(F11,Tabelle1!$A$2:$L$496,12,0)) | R11: Other (IU, Oral, Pessary, Footbath) | T11: =SUM(T13:T16) -> 0 | U11: =SUM(U13:U16) -> 0
D12: =IF(K12="","",VLOOKUP(F12,Tabelle1!$A$2:$C$496,3,0)) | E12: =IF(K12="","",VLOOKUP(F12,Tabelle1!$A$2:$M$496,13,0)) | K12: =IF(F12="","",C13*G12*H12) | L12: =IF(K12="","",VLOOKUP(F12,Tabelle1!$A$2:$I$496,9,0)) | M12: =IF(K12="","",VLOOKUP(F12,Tabelle1!$A$2:$G$496,7,0)) | N12: =IF(M12>0,O12,"") | O12: =IF(K12="","",((K12*VLOOKUP(F12,Tabelle1!$A$2:$I$496,8,0))/$W$4)) | P12: =IF(K12="","",VLOOKUP(F12,Tabelle1!$A$2:$L$496,12,0)) | R12: Total | T12: =SUM(T8:T11) -> 0 | U12: =SUM(U8:U11) -> 0 | V12: =T12+U12 -> 0
D13: =IF(K13="","",VLOOKUP(F13,Tabelle1!$A$2:$C$496,3,0)) | E13: =IF(K13="","",VLOOKUP(F13,Tabelle1!$A$2:$M$496,13,0)) | K13: =IF(F13="","",C14*G13*H13) | L13: =IF(K13="","",VLOOKUP(F13,Tabelle1!$A$2:$I$496,9,0)) | M13: =IF(K13="","",VLOOKUP(F13,Tabelle1!$A$2:$G$496,7,0)) | N13: =IF(M13>0,O13,"") | O13: =IF(K13="","",((K13*VLOOKUP(F13,Tabelle1!$A$2:$I$496,8,0))/$W$4)) | P13: =IF(K13="","",VLOOKUP(F13,Tabelle1!$A$2:$L$496,12,0)) | R13: Footbath | T13: =SUMIFS($O$4:$O$265,$M$4:$M$265,"0",$D$4:$D$265,R13) -> 0 | U13: =SUMIFS($O$4:$O$265,$M$4:$M$265,"1",$D$4:$D$265,R13) -> 0
D14: =IF(K14="","",VLOOKUP(F14,Tabelle1!$A$2:$C$496,3,0)) | E14: =IF(K14="","",VLOOKUP(F14,Tabelle1!$A$2:$M$496,13,0)) | K14: =IF(F14="","",C15*G14*H14) | L14: =IF(K14="","",VLOOKUP(F14,Tabelle1!$A$2:$I$496,9,0)) | M14: =IF(K14="","",VLOOKUP(F14,Tabelle1!$A$2:$G$496,7,0)) | N14: =IF(M14>0,O14,"") | O14: =IF(K14="","",((K14*VLOOKUP(F14,Tabelle1!$A$2:$I$496,8,0))/$W$4)) | P14: =IF(K14="","",VLOOKUP(F14,Tabelle1!$A$2:$L$496,12,0)) | R14: IU | T14: =SUMIFS($O$4:$O$265,$M$4:$M$265,"0",$D$4:$D$265,R14) -> 0 | U14: =SUMIFS($O$4:$O$265,$M$4:$M$265,"1",$D$4:$D$265,R14) -> 0
D15: =IF(K15="","",VLOOKUP(F15,Tabelle1!$A$2:$C$496,3,0)) | E15: =IF(K15="","",VLOOKUP(F15,Tabelle1!$A$2:$M$496,13,0)) | K15: =IF(F15="","",C16*G15*H15) | L15: =IF(K15="","",VLOOKUP(F15,Tabelle1!$A$2:$I$496,9,0)) | M15: =IF(K15="","",VLOOKUP(F15,Tabelle1!$A$2:$G$496,7,0)) | N15: =IF(M15>0,O15,"") | O15: =IF(K15="","",((K15*VLOOKUP(F15,Tabelle1!$A$2:$I$496,8,0))/$W$4)) | P15: =IF(K15="","",VLOOKUP(F15,Tabelle1!$A$2:$L$496,12,0)) | R15: Oral | T15: =SUMIFS($O$4:$O$265,$M$4:$M$265,"0",$D$4:$D$265,R15) -> 0 | U15: =SUMIFS($O$4:$O$265,$M$4:$M$265,"1",$D$4:$D$265,R15) -> 0
D16: =IF(K16="","",VLOOKUP(F16,Tabelle1!$A$2:$C$496,3,0)) | E16: =IF(K16="","",VLOOKUP(F16,Tabelle1!$A$2:$M$496,13,0)) | K16: =IF(F16="","",C16*G16*H16) | L16: =IF(K16="","",VLOOKUP(F16,Tabelle1!$A$2:$I$496,9,0)) | M16: =IF(K16="","",VLOOKUP(F16,Tabelle1!$A$2:$G$496,7,0)) | N16: =IF(M16>0,O16,"") | O16: =IF(K16="","",((K16*VLOOKUP(F16,Tabelle1!$A$2:$I$496,8,0))/$W$4)) | P16: =IF(K16="","",VLOOKUP(F16,Tabelle1!$A$2:$L$496,12,0)) | R16: Pessary | T16: =SUMIFS($O$4:$O$265,$M$4:$M$265,"0",$D$4:$D$265,R16) -> 0 | U16: =SUMIFS($O$4:$O$265,$M$4:$M$265,"1",$D$4:$D$265,R16) -> 0
D17: =IF(K17="","",VLOOKUP(F17,Tabelle1!$A$2:$C$496,3,0)) | E17: =IF(K17="","",VLOOKUP(F17,Tabelle1!$A$2:$M$496,13,0)) | K17: =IF(F17="","",C17*G17*H17) | L17: =IF(K17="","",VLOOKUP(F17,Tabelle1!$A$2:$I$496,9,0)) | M17: =IF(K17="","",VLOOKUP(F17,Tabelle1!$A$2:$G$496,7,0)) | N17: =IF(M17>0,O17,"") | O17: =IF(K17="","",((K17*VLOOKUP(F17,Tabelle1!$A$2:$I$496,8,0))/$W$4)) | P17: =IF(K17="","",VLOOKUP(F17,Tabelle1!$A$2:$L$496,12,0))
D18: =IF(K18="","",VLOOKUP(F18,Tabelle1!$A$2:$C$496,3,0)) | E18: =IF(K18="","",VLOOKUP(F18,Tabelle1!$A$2:$M$496,13,0)) | K18: =IF(F18="","",C18*G18*H18) | L18: =IF(K18="","",VLOOKUP(F18,Tabelle1!$A$2:$I$496,9,0)) | M18: =IF(K18="","",VLOOKUP(F18,Tabelle1!$A$2:$G$496,7,0)) | N18: =IF(M18>0,O18,"") | O18: =IF(K18="","",((K18*VLOOKUP(F18,Tabelle1!$A$2:$I$496,8,0))/$W$4)) | P18: =IF(K18="","",VLOOKUP(F18,Tabelle1!$A$2:$L$496,12,0))
D19: =IF(K19="","",VLOOKUP(F19,Tabelle1!$A$2:$C$496,3,0)) | E19: =IF(K19="","",VLOOKUP(F19,Tabelle1!$A$2:$M$496,13,0)) | K19: =IF(F19="","",C19*G19*H19) | L19: =IF(K19="","",VLOOKUP(F19,Tabelle1!$A$2:$I$496,9,0)) | M19: =IF(K19="","",VLOOKUP(F19,Tabelle1!$A$2:$G$496,7,0)) | N19: =IF(M19>0,O19,"") | O19: =IF(K19="","",((K19*VLOOKUP(F19,Tabelle1!$A$2:$I$496,8,0))/$W$4)) | P19: =IF(K19="","",VLOOKUP(F19,Tabelle1!$A$2:$L$496,12,0))
D20: =IF(K20="","",VLOOKUP(F20,Tabelle1!$A$2:$C$496,3,0)) | E20: =IF(K20="","",VLOOKUP(F20,Tabelle1!$A$2:$M$496,13,0)) | K20: =IF(F20="","",C20*G20*H20) | L20: =IF(K20="","",VLOOKUP(F20,Tabelle1!$A$2:$I$496,9,0)) | M20: =IF(K20="","",VLOOKUP(F20,Tabelle1!$A$2:$G$496,7,0)) | N20: =IF(M20>0,O20,"") | O20: =IF(K20="","",((K20*VLOOKUP(F20,Tabelle1!$A$2:$I$496,8,0))/$W$4)) | P20: =IF(K20="","",VLOOKUP(F20,Tabelle1!$A$2:$L$496,12,0))
D21: =IF(K21="","",VLOOKUP(F21,Tabelle1!$A$2:$C$496,3,0)) | E21: =IF(K21="","",VLOOKUP(F21,Tabelle1!$A$2:$M$496,13,0)) | K21: =IF(F21="","",C21*G21*H21) | L21: =IF(K21="","",VLOOKUP(F21,Tabelle1!$A$2:$I$496,9,0)) | M21: =IF(K21="","",VLOOKUP(F21,Tabelle1!$A$2:$G$496,7,0)) | N21: =IF(M21>0,O21,"") | O21: =IF(K21="","",((K21*VLOOKUP(F21,Tabelle1!$A$2:$I$496,8,0))/$W$4)) | P21: =IF(K21="","",VLOOKUP(F21,Tabelle1!$A$2:$L$496,12,0))
D22: =IF(K22="","",VLOOKUP(F22,Tabelle1!$A$2:$C$496,3,0)) | E22: =IF(K22="","",VLOOKUP(F22,Tabelle1!$A$2:$M$496,13,0)) | K22: =IF(F22="","",C22*G22*H22) | L22: =IF(K22="","",VLOOKUP(F22,Tabelle1!$A$2:$I$496,9,0)) | M22: =IF(K22="","",VLOOKUP(F22,Tabelle1!$A$2:$G$496,7,0)) | N22: =IF(M22>0,O22,"") | O22: =IF(K22="","",((K22*VLOOKUP(F22,Tabelle1!$A$2:$I$496,8,0))/$W$4)) | P22: =IF(K22="","",VLOOKUP(F22,Tabelle1!$A$2:$L$496,12,0))
D23: =IF(K23="","",VLOOKUP(F23,Tabelle1!$A$2:$C$496,3,0)) | E23: =IF(K23="","",VLOOKUP(F23,Tabelle1!$A$2:$M$496,13,0)) | K23: =IF(F23="","",C23*G23*H23) | L23: =IF(K23="","",VLOOKUP(F23,Tabelle1!$A$2:$I$496,9,0)) | M23: =IF(K23="","",VLOOKUP(F23,Tabelle1!$A$2:$G$496,7,0)) | N23: =IF(M23>0,O23,"") | O23: =IF(K23="","",((K23*VLOOKUP(F23,Tabelle1!$A$2:$I$496,8,0))/$W$4)) | P23: =IF(K23="","",VLOOKUP(F23,Tabelle1!$A$2:$L$496,12,0))
D24: =IF(K24="","",VLOOKUP(F24,Tabelle1!$A$2:$C$496,3,0)) | E24: =IF(K24="","",VLOOKUP(F24,Tabelle1!$A$2:$M$496,13,0)) | K24: =IF(F24="","",C24*G24*H24) | L24: =IF(K24="","",VLOOKUP(F24,Tabelle1!$A$2:$I$496,9,0)) | M24: =IF(K24="","",VLOOKUP(F24,Tabelle1!$A$2:$G$496,7,0)) | N24: =IF(M24>0,O24,"") | O24: =IF(K24="","",((K24*VLOOKUP(F24,Tabelle1!$A$2:$I$496,8,0))/$W$4)) | P24: =IF(K24="","",VLOOKUP(F24,Tabelle1!$A$2:$L$496,12,0))
D25: =IF(K25="","",VLOOKUP(F25,Tabelle1!$A$2:$C$496,3,0)) | E25: =IF(K25="","",VLOOKUP(F25,Tabelle1!$A$2:$M$496,13,0)) | K25: =IF(F25="","",C25*G25*H25) | L25: =IF(K25="","",VLOOKUP(F25,Tabelle1!$A$2:$I$496,9,0)) | M25: =IF(K25="","",VLOOKUP(F25,Tabelle1!$A$2:$G$496,7,0)) | N25: =IF(M25>0,O25,"") | O25: =IF(K25="","",((K25*VLOOKUP(F25,Tabelle1!$A$2:$I$496,8,0))/$W$4)) | P25: =IF(K25="","",VLOOKUP(F25,Tabelle1!$A$2:$L$496,12,0))
D26: =IF(K26="","",VLOOKUP(F26,Tabelle1!$A$2:$C$496,3,0)) | E26: =IF(K26="","",VLOOKUP(F26,Tabelle1!$A$2:$M$496,13,0)) | K26: =IF(F26="","",C26*G26*H26) | L26: =IF(K26="","",VLOOKUP(F26,Tabelle1!$A$2:$I$496,9,0)) | M26: =IF(K26="","",VLOOKUP(F26,Tabelle1!$A$2:$G$496,7,0)) | N26: =IF(M26>0,O26,"") | O26: =IF(K26="","",((K26*VLOOKUP(F26,Tabelle1!$A$2:$I$496,8,0))/$W$4)) | P26: =IF(K26="","",VLOOKUP(F26,Tabelle1!$A$2:$L$496,12,0))
D27: =IF(K27="","",VLOOKUP(F27,Tabelle1!$A$2:$C$496,3,0)) | E27: =IF(K27="","",VLOOKUP(F27,Tabelle1!$A$2:$M$496,13,0)) | K27: =IF(F27="","",C27*G27*H27) | L27: =IF(K27="","",VLOOKUP(F27,Tabelle1!$A$2:$I$496,9,0)) | M27: =IF(K27="","",VLOOKUP(F27,Tabelle1!$A$2:$G$496,7,0)) | N27: =IF(M27>0,O27,"") | O27: =IF(K27="","",((K27*VLOOKUP(F27,Tabelle1!$A$2:$I$496,8,0))/$W$4)) | P27: =IF(K27="","",VLOOKUP(F27,Tabelle1!$A$2:$L$496,12,0))
D28: =IF(K28="","",VLOOKUP(F28,Tabelle1!$A$2:$C$496,3,0)) | E28: =IF(K28="","",VLOOKUP(F28,Tabelle1!$A$2:$M$496,13,0)) | K28: =IF(F28="","",C28*G28*H28) | L28: =IF(K28="","",VLOOKUP(F28,Tabelle1!$A$2:$I$496,9,0)) | M28: =IF(K28="","",VLOOKUP(F28,Tabelle1!$A$2:$G$496,7,0)) | N28: =IF(M28>0,O28,"") | O28: =IF(K28="","",((K28*VLOOKUP(F28,Tabelle1!$A$2:$I$496,8,0))/$W$4)) | P28: =IF(K28="","",VLOOKUP(F28,Tabelle1!$A$2:$L$496,12,0))
... D41: =IF(K41="","",VLOOKUP(F41,Tabelle1!$A$2:$C$496,3,0)) | E41: =IF(K41="","",VLOOKUP(F41,Tabelle1!$A$2:$M$496,13,0)) | K41: =IF(F41="","",C41*G41*H41) | L41: =IF(K41="","",VLOOKUP(F41,Tabelle1!$A$2:$I$496,9,0)) | M41: =IF(K41="","",VLOOKUP(F41,Tabelle1!$A$2:$G$496,7,0)) | N41: =IF(M41>0,O41,"") | O41: =IF(K41="","",((K41*VLOOKUP(F41,Tabelle1!$A$2:$I$496,8,0))/$W$4)) | P41: =IF(K41="","",VLOOKUP(F41,Tabelle1!$A$2:$L$496,12,0))
D42: =IF(K42="","",VLOOKUP(F42,Tabelle1!$A$2:$C$496,3,0)) | E42: =IF(K42="","",VLOOKUP(F42,Tabelle1!$A$2:$M$496,13,0)) | K42: =IF(F42="","",C42*G42*H42) | L42: =IF(K42="","",VLOOKUP(F42,Tabelle1!$A$2:$I$496,9,0)) | M42: =IF(K42="","",VLOOKUP(F42,Tabelle1!$A$2:$G$496,7,0)) | N42: =IF(M42>0,O42,"") | O42: =IF(K42="","",((K42*VLOOKUP(F42,Tabelle1!$A$2:$I$496,8,0))/$W$4)) | P42: =IF(K42="","",VLOOKUP(F42,Tabelle1!$A$2:$L$496,12,0)) | R42: Waga zwierząt
D43: =IF(K43="","",VLOOKUP(F43,Tabelle1!$A$2:$C$496,3,0)) | E43: =IF(K43="","",VLOOKUP(F43,Tabelle1!$A$2:$M$496,13,0)) | K43: =IF(F43="","",C43*G43*H43) | L43: =IF(K43="","",VLOOKUP(F43,Tabelle1!$A$2:$I$496,9,0)) | M43: =IF(K43="","",VLOOKUP(F43,Tabelle1!$A$2:$G$496,7,0)) | N43: =IF(M43>0,O43,"") | O43: =IF(K43="","",((K43*VLOOKUP(F43,Tabelle1!$A$2:$I$496,8,0))/$W$4)) | P43: =IF(K43="","",VLOOKUP(F43,Tabelle1!$A$2:$L$496,12,0))
D44: =IF(K44="","",VLOOKUP(F44,Tabelle1!$A$2:$C$496,3,0)) | E44: =IF(K44="","",VLOOKUP(F44,Tabelle1!$A$2:$M$496,13,0)) | K44: =IF(F44="","",C44*G44*H44) | L44: =IF(K44="","",VLOOKUP(F44,Tabelle1!$A$2:$I$496,9,0)) | M44: =IF(K44="","",VLOOKUP(F44,Tabelle1!$A$2:$G$496,7,0)) | N44: =IF(M44>0,O44,"") | O44: =IF(K44="","",((K44*VLOOKUP(F44,Tabelle1!$A$2:$I$496,8,0))/$W$4)) | P44: =IF(K44="","",VLOOKUP(F44,Tabelle1!$A$2:$L$496,12,0)) | R44: Live weight unit | S44: Kilograms | U44: Total PCU
D45: =IF(K45="","",VLOOKUP(F45,Tabelle1!$A$2:$C$496,3,0)) | E45: =IF(K45="","",VLOOKUP(F45,Tabelle1!$A$2:$M$496,13,0)) | K45: =IF(F45="","",C45*G45*H45) | L45: =IF(K45="","",VLOOKUP(F45,Tabelle1!$A$2:$I$496,9,0)) | M45: =IF(K45="","",VLOOKUP(F45,Tabelle1!$A$2:$G$496,7,0)) | N45: =IF(M45>0,O45,"") | O45: =IF(K45="","",((K45*VLOOKUP(F45,Tabelle1!$A$2:$I$496,8,0))/$W$4)) | P45: =IF(K45="","",VLOOKUP(F45,Tabelle1!$A$2:$L$496,12,0)) | S45: On-farm animals | U45: =(S47*T47)+(S48*T48)+(S49*T49)+(S50*T50)+(S51*T51)+(S52*T52) -> 0
D46: =IF(K46="","",VLOOKUP(F46,Tabelle1!$A$2:$C$496,3,0)) | E46: =IF(K46="","",VLOOKUP(F46,Tabelle1!$A$2:$M$496,13,0)) | K46: =IF(F46="","",C46*G46*H46) | L46: =IF(K46="","",VLOOKUP(F46,Tabelle1!$A$2:$I$496,9,0)) | M46: =IF(K46="","",VLOOKUP(F46,Tabelle1!$A$2:$G$496,7,0)) | N46: =IF(M46>0,O46,"") | O46: =IF(K46="","",((K46*VLOOKUP(F46,Tabelle1!$A$2:$I$496,8,0))/$W$4)) | P46: =IF(K46="","",VLOOKUP(F46,Tabelle1!$A$2:$L$496,12,0)) | R46: Category | S46: Number | T46: Live weight
D47: =IF(K47="","",VLOOKUP(F47,Tabelle1!$A$2:$C$496,3,0)) | E47: =IF(K47="","",VLOOKUP(F47,Tabelle1!$A$2:$M$496,13,0)) | K47: =IF(F47="","",C47*G47*H47) | L47: =IF(K47="","",VLOOKUP(F47,Tabelle1!$A$2:$I$496,9,0)) | M47: =IF(K47="","",VLOOKUP(F47,Tabelle1!$A$2:$G$496,7,0)) | N47: =IF(M47>0,O47,"") | O47: =IF(K47="","",((K47*VLOOKUP(F47,Tabelle1!$A$2:$I$496,8,0))/$W$4)) | P47: =IF(K47="","",VLOOKUP(F47,Tabelle1!$A$2:$L$496,12,0)) | R47: Dairy cows | S47: ='Karta informacyjna'!D8 -> 0 | T47: 425
D48: =IF(K48="","",VLOOKUP(F48,Tabelle1!$A$2:$C$496,3,0)) | E48: =IF(K48="","",VLOOKUP(F48,Tabelle1!$A$2:$M$496,13,0)) | K48: =IF(F48="","",C48*G48*H48) | L48: =IF(K48="","",VLOOKUP(F48,Tabelle1!$A$2:$I$496,9,0)) | M48: =IF(K48="","",VLOOKUP(F48,Tabelle1!$A$2:$G$496,7,0)) | N48: =IF(M48>0,O48,"") | O48: =IF(K48="","",((K48*VLOOKUP(F48,Tabelle1!$A$2:$I$496,8,0))/$W$4)) | P48: =IF(K48="","",VLOOKUP(F48,Tabelle1!$A$2:$L$496,12,0)) | R48: Dry cows
D49: =IF(K49="","",VLOOKUP(F49,Tabelle1!$A$2:$C$496,3,0)) | E49: =IF(K49="","",VLOOKUP(F49,Tabelle1!$A$2:$M$496,13,0)) | K49: =IF(F49="","",C49*G49*H49) | L49: =IF(K49="","",VLOOKUP(F49,Tabelle1!$A$2:$I$496,9,0)) | M49: =IF(K49="","",VLOOKUP(F49,Tabelle1!$A$2:$G$496,7,0)) | N49: =IF(M49>0,O49,"") | O49: =IF(K49="","",((K49*VLOOKUP(F49,Tabelle1!$A$2:$I$496,8,0))/$W$4)) | P49: =IF(K49="","",VLOOKUP(F49,Tabelle1!$A$2:$L$496,12,0)) | R49: Calves | S49: ='Karta informacyjna'!D10 -> 0 | T49: 140
D50: =IF(K50="","",VLOOKUP(F50,Tabelle1!$A$2:$C$496,3,0)) | E50: =IF(K50="","",VLOOKUP(F50,Tabelle1!$A$2:$M$496,13,0)) | K50: =IF(F50="","",C50*G50*H50) | L50: =IF(K50="","",VLOOKUP(F50,Tabelle1!$A$2:$I$496,9,0)) | M50: =IF(K50="","",VLOOKUP(F50,Tabelle1!$A$2:$G$496,7,0)) | N50: =IF(M50>0,O50,"") | O50: =IF(K50="","",((K50*VLOOKUP(F50,Tabelle1!$A$2:$I$496,8,0))/$W$4)) | P50: =IF(K50="","",VLOOKUP(F50,Tabelle1!$A$2:$L$496,12,0)) | R50: Heifers | S50: ='Karta informacyjna'!D9 -> 0 | T50: 200
D51: =IF(K51="","",VLOOKUP(F51,Tabelle1!$A$2:$C$496,3,0)) | E51: =IF(K51="","",VLOOKUP(F51,Tabelle1!$A$2:$M$496,13,0)) | K51: =IF(F51="","",C51*G51*H51) | L51: =IF(K51="","",VLOOKUP(F51,Tabelle1!$A$2:$I$496,9,0)) | M51: =IF(K51="","",VLOOKUP(F51,Tabelle1!$A$2:$G$496,7,0)) | N51: =IF(M51>0,O51,"") | O51: =IF(K51="","",((K51*VLOOKUP(F51,Tabelle1!$A$2:$I$496,8,0))/$W$4)) | P51: =IF(K51="","",VLOOKUP(F51,Tabelle1!$A$2:$L$496,12,0)) | R51: Steers
D52: =IF(K52="","",VLOOKUP(F52,Tabelle1!$A$2:$C$496,3,0)) | E52: =IF(K52="","",VLOOKUP(F52,Tabelle1!$A$2:$M$496,13,0)) | K52: =IF(F52="","",C52*G52*H52) | L52: =IF(K52="","",VLOOKUP(F52,Tabelle1!$A$2:$I$496,9,0)) | M52: =IF(K52="","",VLOOKUP(F52,Tabelle1!$A$2:$G$496,7,0)) | N52: =IF(M52>0,O52,"") | O52: =IF(K52="","",((K52*VLOOKUP(F52,Tabelle1!$A$2:$I$496,8,0))/$W$4)) | P52: =IF(K52="","",VLOOKUP(F52,Tabelle1!$A$2:$L$496,12,0)) | R52: Bulls | S52: ='Karta informacyjna'!D11 -> 0 | T52: 425
...

Sheet Mastitis
A1: Mastitis
J2: =SUM(J4:J265) -> 0 | M2: =SUM(M4:M265) -> 0 | N2: =SUM(N4:N265) -> 0 | O2: =SUM(O4:O265) -> 0
A3: Data | B3: Kategoria bydła | C3: Liczba leczonych zwierząt | D3: Sposób podania (Route) | E3: Ryzyko powstawania oporności 1-6 | F3: Antybiotyk (nazwa preparatu w tubostrzykawce) (Product) | G3: Dawka dzienna | H3: Liczba tubostrzykawek (przez cały okres leczenia) (liczba podań) | I3: Rozpoznanie (Treatments) | J3: Antybiogram [0=nie; 1=tak] | K3: Liczba tubostrzykawek (przez cały okres leczenia) (liczba podań) (Amount used) | L3: Jednostka (Unit) | M3: Krytyczny [0=nie; 1=tak (Critical) [0 = no; 1 = yes] | N3: Antybiotyki krytyczne [mg/PCU] (Critically Important) [mg/PCU] | O3: Zużycie antybiotyków [mg/PCU] (Antibiotic Use) [mg/PCU] | P3: Klasa EMA A-D | T3: Total Antibiotic Use [mg/PCU] | U3: Total Critically Important [mg/PCU] | W3: Total PCU
B4: Krowa | C4: 6 | D4: =IF(K4="","",VLOOKUP(F4,Tabelle1!$A$2:$C$496,3,0)) | E4: =IF(K4="","",VLOOKUP(F4,Tabelle1!$A$2:$M$496,13,0)) | L4: =IF(K4="","",VLOOKUP(F4,Tabelle1!$A$2:$I$496,9,0)) | M4: =IF(K4="","",VLOOKUP(F4,Tabelle1!$A$2:$G$496,7,0)) | N4: =IF(M4>0,O4,"") | O4: =IF(K4="","",((K4*VLOOKUP(F4,Tabelle1!$A$2:$I$496,8,0))/$W$4)) | P4: =IF(K4="","",VLOOKUP(F4,Tabelle1!$A$2:$L$496,12,0)) | R4: Total mg/PCU in herd | T4: =(SUM(O4:O265)) -> 0 | U4: =SUM(N4:N265) -> 0 | W4: =U45 -> 0
B5: Krowa | C5: 7 | D5: =IF(K5="","",VLOOKUP(F5,Tabelle1!$A$2:$C$496,3,0)) | E5: =IF(K5="","",VLOOKUP(F5,Tabelle1!$A$2:$M$496,13,0)) | L5: =IF(K5="","",VLOOKUP(F5,Tabelle1!$A$2:$I$496,9,0)) | M5: =IF(K5="","",VLOOKUP(F5,Tabelle1!$A$2:$G$496,7,0)) | N5: =IF(M5>0,O5,"") | O5: =IF(K5="","",((K5*VLOOKUP(F5,Tabelle1!$A$2:$I$496,8,0))/$W$4)) | P5: =IF(K5="","",VLOOKUP(F5,Tabelle1!$A$2:$L$496,12,0))
B6: Krowa | C6: 8 | D6: =IF(K6="","",VLOOKUP(F6,Tabelle1!$A$2:$C$496,3,0)) | E6: =IF(K6="","",VLOOKUP(F6,Tabelle1!$A$2:$M$496,13,0)) | L6: =IF(K6="","",VLOOKUP(F6,Tabelle1!$A$2:$I$496,9,0)) | M6: =IF(K6="","",VLOOKUP(F6,Tabelle1!$A$2:$G$496,7,0)) | N6: =IF(M6>0,O6,"") | O6: =IF(K6="","",((K6*VLOOKUP(F6,Tabelle1!$A$2:$I$496,8,0))/$W$4)) | P6: =IF(K6="","",VLOOKUP(F6,Tabelle1!$A$2:$L$496,12,0))
B7: Krowa | C7: 9 | D7: =IF(K7="","",VLOOKUP(F7,Tabelle1!$A$2:$C$496,3,0)) | E7: =IF(K7="","",VLOOKUP(F7,Tabelle1!$A$2:$M$496,13,0)) | L7: =IF(K7="","",VLOOKUP(F7,Tabelle1!$A$2:$I$496,9,0)) | M7: =IF(K7="","",VLOOKUP(F7,Tabelle1!$A$2:$G$496,7,0)) | N7: =IF(M7>0,O7,"") | O7: =IF(K7="","",((K7*VLOOKUP(F7,Tabelle1!$A$2:$I$496,8,0))/$W$4)) | P7: =IF(K7="","",VLOOKUP(F7,Tabelle1!$A$2:$L$496,12,0)) | R7: Route | T7: Antibiotic Use [mg/PCU] | U7: Critically Important [mg/PCU]
B8: Krowa | C8: 10 | D8: =IF(K8="","",VLOOKUP(F8,Tabelle1!$A$2:$C$496,3,0)) | E8: =IF(K8="","",VLOOKUP(F8,Tabelle1!$A$2:$M$496,13,0)) | L8: =IF(K8="","",VLOOKUP(F8,Tabelle1!$A$2:$I$496,9,0)) | M8: =IF(K8="","",VLOOKUP(F8,Tabelle1!$A$2:$G$496,7,0)) | N8: =IF(M8>0,O8,"") | O8: =IF(K8="","",((K8*VLOOKUP(F8,Tabelle1!$A$2:$I$496,8,0))/$W$4)) | P8: =IF(K8="","",VLOOKUP(F8,Tabelle1!$A$2:$L$496,12,0)) | R8: Injectable | T8: =SUMIFS($O$4:$O$265,$M$4:$M$265,"0",$D$4:$D$265,R8) -> 0 | U8: =SUMIFS($O$4:$O$265,$M$4:$M$265,"1",$D$4:$D$265,R8) -> 0
B9: Krowa | C9: 11 | D9: =IF(K9="","",VLOOKUP(F9,Tabelle1!$A$2:$C$496,3,0)) | E9: =IF(K9="","",VLOOKUP(F9,Tabelle1!$A$2:$M$496,13,0)) | L9: =IF(K9="","",VLOOKUP(F9,Tabelle1!$A$2:$I$496,9,0)) | M9: =IF(K9="","",VLOOKUP(F9,Tabelle1!$A$2:$G$496,7,0)) | N9: =IF(M9>0,O9,"") | O9: =IF(K9="","",((K9*VLOOKUP(F9,Tabelle1!$A$2:$I$496,8,0))/$W$4)) | P9: =IF(K9="","",VLOOKUP(F9,Tabelle1!$A$2:$L$496,12,0)) | R9: Lactatingtube | T9: =SUMIFS($O$4:$O$265,$M$4:$M$265,"0",$D$4:$D$265,R9) -> 0 | U9: =SUMIFS($O$4:$O$265,$M$4:$M$265,"1",$D$4:$D$265,R9) -> 0
B10: Krowa | C10: 12 | D10: =IF(K10="","",VLOOKUP(F10,Tabelle1!$A$2:$C$496,3,0)) | E10: =IF(K10="","",VLOOKUP(F10,Tabelle1!$A$2:$M$496,13,0)) | L10: =IF(K10="","",VLOOKUP(F10,Tabelle1!$A$2:$I$496,9,0)) | M10: =IF(K10="","",VLOOKUP(F10,Tabelle1!$A$2:$G$496,7,0)) | N10: =IF(M10>0,O10,"") | O10: =IF(K10="","",((K10*VLOOKUP(F10,Tabelle1!$A$2:$I$496,8,0))/$W$4)) | P10: =IF(K10="","",VLOOKUP(F10,Tabelle1!$A$2:$L$496,12,0)) | R10: Drytube | T10: =SUMIFS($O$4:$O$265,$M$4:$M$265,"0",$D$4:$D$265,R10) -> 0 | U10: =SUMIFS($O$4:$O$265,$M$4:$M$265,"1",$D$4:$D$265,R10) -> 0
B11: Krowa | C11: 13 | D11: =IF(K11="","",VLOOKUP(F11,Tabelle1!$A$2:$C$496,3,0)) | E11: =IF(K11="","",VLOOKUP(F11,Tabelle1!$A$2:$M$496,13,0)) | L11: =IF(K11="","",VLOOKUP(F11,Tabelle1!$A$2:$I$496,9,0)) | M11: =IF(K11="","",VLOOKUP(F11,Tabelle1!$A$2:$G$496,7,0)) | N11: =IF(M11>0,O11,"") | O11: =IF(K11="","",((K11*VLOOKUP(F11,Tabelle1!$A$2:$I$496,8,0))/$W$4)) | P11: =IF(K11="","",VLOOKUP(F11,Tabelle1!$A$2:$L$496,12,0)) | R11: Other (IU, Oral, Pessary, Footbath) | T11: =SUM(T13:T16) -> 0 | U11: =SUM(U13:U16) -> 0
B12: Krowa | C12: 14 | D12: =IF(K12="","",VLOOKUP(F12,Tabelle1!$A$2:$C$496,3,0)) | E12: =IF(K12="","",VLOOKUP(F12,Tabelle1!$A$2:$M$496,13,0)) | L12: =IF(K12="","",VLOOKUP(F12,Tabelle1!$A$2:$I$496,9,0)) | M12: =IF(K12="","",VLOOKUP(F12,Tabelle1!$A$2:$G$496,7,0)) | N12: =IF(M12>0,O12,"") | O12: =IF(K12="","",((K12*VLOOKUP(F12,Tabelle1!$A$2:$I$496,8,0))/$W$4)) | P12: =IF(K12="","",VLOOKUP(F12,Tabelle1!$A$2:$L$496,12,0)) | R12: Total | T12: =SUM(T8:T11) -> 0 | U12: =SUM(U8:U11) -> 0 | V12: =T12+U12 -> 0
B13: Krowa | C13: 15 | D13: =IF(K13="","",VLOOKUP(F13,Tabelle1!$A$2:$C$496,3,0)) | E13: =IF(K13="","",VLOOKUP(F13,Tabelle1!$A$2:$M$496,13,0)) | L13: =IF(K13="","",VLOOKUP(F13,Tabelle1!$A$2:$I$496,9,0)) | M13: =IF(K13="","",VLOOKUP(F13,Tabelle1!$A$2:$G$496,7,0)) | N13: =IF(M13>0,O13,"") | O13: =IF(K13="","",((K13*VLOOKUP(F13,Tabelle1!$A$2:$I$496,8,0))/$W$4)) | P13: =IF(K13="","",VLOOKUP(F13,Tabelle1!$A$2:$L$496,12,0)) | R13: Footbath | T13: =SUMIFS($O$4:$O$265,$M$4:$M$265,"0",$D$4:$D$265,R13) -> 0 | U13: =SUMIFS($O$4:$O$265,$M$4:$M$265,"1",$D$4:$D$265,R13) -> 0
B14: Krowa | C14: 16 | D14: =IF(K14="","",VLOOKUP(F14,Tabelle1!$A$2:$C$496,3,0)) | E14: =IF(K14="","",VLOOKUP(F14,Tabelle1!$A$2:$M$496,13,0)) | L14: =IF(K14="","",VLOOKUP(F14,Tabelle1!$A$2:$I$496,9,0)) | M14: =IF(K14="","",VLOOKUP(F14,Tabelle1!$A$2:$G$496,7,0)) | N14: =IF(M14>0,O14,"") | O14: =IF(K14="","",((K14*VLOOKUP(F14,Tabelle1!$A$2:$I$496,8,0))/$W$4)) | P14: =IF(K14="","",VLOOKUP(F14,Tabelle1!$A$2:$L$496,12,0)) | R14: IU | T14: =SUMIFS($O$4:$O$265,$M$4:$M$265,"0",$D$4:$D$265,R14) -> 0 | U14: =SUMIFS($O$4:$O$265,$M$4:$M$265,"1",$D$4:$D$265,R14) -> 0
B15: Krowa | C15: 17 | D15: =IF(K15="","",VLOOKUP(F15,Tabelle1!$A$2:$C$496,3,0)) | E15: =IF(K15="","",VLOOKUP(F15,Tabelle1!$A$2:$M$496,13,0)) | L15: =IF(K15="","",VLOOKUP(F15,Tabelle1!$A$2:$I$496,9,0)) | M15: =IF(K15="","",VLOOKUP(F15,Tabelle1!$A$2:$G$496,7,0)) | N15: =IF(M15>0,O15,"") | O15: =IF(K15="","",((K15*VLOOKUP(F15,Tabelle1!$A$2:$I$496,8,0))/$W$4)) | P15: =IF(K15="","",VLOOKUP(F15,Tabelle1!$A$2:$L$496,12,0)) | R15: Oral | T15: =SUMIFS($O$4:$O$265,$M$4:$M$265,"0",$D$4:$D$265,R15) -> 0 | U15: =SUMIFS($O$4:$O$265,$M$4:$M$265,"1",$D$4:$D$265,R15) -> 0
B16: Krowa | C16: 18 | D16: =IF(K16="","",VLOOKUP(F16,Tabelle1!$A$2:$C$496,3,0)) | E16: =IF(K16="","",VLOOKUP(F16,Tabelle1!$A$2:$M$496,13,0)) | L16: =IF(K16="","",VLOOKUP(F16,Tabelle1!$A$2:$I$496,9,0)) | M16: =IF(K16="","",VLOOKUP(F16,Tabelle1!$A$2:$G$496,7,0)) | N16: =IF(M16>0,O16,"") | O16: =IF(K16="","",((K16*VLOOKUP(F16,Tabelle1!$A$2:$I$496,8,0))/$W$4)) | P16: =IF(K16="","",VLOOKUP(F16,Tabelle1!$A$2:$L$496,12,0)) | R16: Pessary | T16: =SUMIFS($O$4:$O$265,$M$4:$M$265,"0",$D$4:$D$265,R16) -> 0 | U16: =SUMIFS($O$4:$O$265,$M$4:$M$265,"1",$D$4:$D$265,R16) -> 0
B17: Krowa | C17: 19 | D17: =IF(K17="","",VLOOKUP(F17,Tabelle1!$A$2:$C$496,3,0)) | E17: =IF(K17="","",VLOOKUP(F17,Tabelle1!$A$2:$M$496,13,0)) | L17: =IF(K17="","",VLOOKUP(F17,Tabelle1!$A$2:$I$496,9,0)) | M17: =IF(K17="","",VLOOKUP(F17,Tabelle1!$A$2:$G$496,7,0)) | N17: =IF(M17>0,O17,"") | O17: =IF(K17="","",((K17*VLOOKUP(F17,Tabelle1!$A$2:$I$496,8,0))/$W$4)) | P17: =IF(K17="","",VLOOKUP(F17,Tabelle1!$A$2:$L$496,12,0))
B18: Krowa | C18: 20 | D18: =IF(K18="","",VLOOKUP(F18,Tabelle1!$A$2:$C$496,3,0)) | E18: =IF(K18="","",VLOOKUP(F18,Tabelle1!$A$2:$M$496,13,0)) | L18: =IF(K18="","",VLOOKUP(F18,Tabelle1!$A$2:$I$496,9,0)) | M18: =IF(K18="","",VLOOKUP(F18,Tabelle1!$A$2:$G$496,7,0)) | N18: =IF(M18>0,O18,"") | O18: =IF(K18="","",((K18*VLOOKUP(F18,Tabelle1!$A$2:$I$496,8,0))/$W$4)) | P18: =IF(K18="","",VLOOKUP(F18,Tabelle1!$A$2:$L$496,12,0))
B19: Krowa | C19: 21 | D19: =IF(K19="","",VLOOKUP(F19,Tabelle1!$A$2:$C$496,3,0)) | E19: =IF(K19="","",VLOOKUP(F19,Tabelle1!$A$2:$M$496,13,0)) | L19: =IF(K19="","",VLOOKUP(F19,Tabelle1!$A$2:$I$496,9,0)) | M19: =IF(K19="","",VLOOKUP(F19,Tabelle1!$A$2:$G$496,7,0)) | N19: =IF(M19>0,O19,"") | O19: =IF(K19="","",((K19*VLOOKUP(F19,Tabelle1!$A$2:$I$496,8,0))/$W$4)) | P19: =IF(K19="","",VLOOKUP(F19,Tabelle1!$A$2:$L$496,12,0))
B20: Krowa | C20: 22 | D20: =IF(K20="","",VLOOKUP(F20,Tabelle1!$A$2:$C$496,3,0)) | E20: =IF(K20="","",VLOOKUP(F20,Tabelle1!$A$2:$M$496,13,0)) | L20: =IF(K20="","",VLOOKUP(F20,Tabelle1!$A$2:$I$496,9,0)) | M20: =IF(K20="","",VLOOKUP(F20,Tabelle1!$A$2:$G$496,7,0)) | N20: =IF(M20>0,O20,"") | O20: =IF(K20="","",((K20*VLOOKUP(F20,Tabelle1!$A$2:$I$496,8,0))/$W$4)) | P20: =IF(K20="","",VLOOKUP(F20,Tabelle1!$A$2:$L$496,12,0)) | Q20: =SUM(O4:O12) -> 0
B21: Krowa | C21: 23 | D21: =IF(K21="","",VLOOKUP(F21,Tabelle1!$A$2:$C$496,3,0)) | E21: =IF(K21="","",VLOOKUP(F21,Tabelle1!$A$2:$M$496,13,0)) | L21: =IF(K21="","",VLOOKUP(F21,Tabelle1!$A$2:$I$496,9,0)) | M21: =IF(K21="","",VLOOKUP(F21,Tabelle1!$A$2:$G$496,7,0)) | N21: =IF(M21>0,O21,"") | O21: =IF(K21="","",((K21*VLOOKUP(F21,Tabelle1!$A$2:$I$496,8,0))/$W$4)) | P21: =IF(K21="","",VLOOKUP(F21,Tabelle1!$A$2:$L$496,12,0))
B22: Krowa | C22: 24 | D22: =IF(K22="","",VLOOKUP(F22,Tabelle1!$A$2:$C$496,3,0)) | E22: =IF(K22="","",VLOOKUP(F22,Tabelle1!$A$2:$M$496,13,0)) | L22: =IF(K22="","",VLOOKUP(F22,Tabelle1!$A$2:$I$496,9,0)) | M22: =IF(K22="","",VLOOKUP(F22,Tabelle1!$A$2:$G$496,7,0)) | N22: =IF(M22>0,O22,"") | O22: =IF(K22="","",((K22*VLOOKUP(F22,Tabelle1!$A$2:$I$496,8,0))/$W$4)) | P22: =IF(K22="","",VLOOKUP(F22,Tabelle1!$A$2:$L$496,12,0))
B23: Krowa | C23: 25 | D23: =IF(K23="","",VLOOKUP(F23,Tabelle1!$A$2:$C$496,3,0)) | E23: =IF(K23="","",VLOOKUP(F23,Tabelle1!$A$2:$M$496,13,0)) | L23: =IF(K23="","",VLOOKUP(F23,Tabelle1!$A$2:$I$496,9,0)) | M23: =IF(K23="","",VLOOKUP(F23,Tabelle1!$A$2:$G$496,7,0)) | N23: =IF(M23>0,O23,"") | O23: =IF(K23="","",((K23*VLOOKUP(F23,Tabelle1!$A$2:$I$496,8,0))/$W$4)) | P23: =IF(K23="","",VLOOKUP(F23,Tabelle1!$A$2:$L$496,12,0))
B24: Krowa | C24: 26 | D24: =IF(K24="","",VLOOKUP(F24,Tabelle1!$A$2:$C$496,3,0)) | E24: =IF(K24="","",VLOOKUP(F24,Tabelle1!$A$2:$M$496,13,0)) | L24: =IF(K24="","",VLOOKUP(F24,Tabelle1!$A$2:$I$496,9,0)) | M24: =IF(K24="","",VLOOKUP(F24,Tabelle1!$A$2:$G$496,7,0)) | N24: =IF(M24>0,O24,"") | O24: =IF(K24="","",((K24*VLOOKUP(F24,Tabelle1!$A$2:$I$496,8,0))/$W$4)) | P24: =IF(K24="","",VLOOKUP(F24,Tabelle1!$A$2:$L$496,12,0))
B25: Krowa | C25: 27 | D25: =IF(K25="","",VLOOKUP(F25,Tabelle1!$A$2:$C$496,3,0)) | E25: =IF(K25="","",VLOOKUP(F25,Tabelle1!$A$2:$M$496,13,0)) | L25: =IF(K25="","",VLOOKUP(F25,Tabelle1!$A$2:$I$496,9,0)) | M25: =IF(K25="","",VLOOKUP(F25,Tabelle1!$A$2:$G$496,7,0)) | N25: =IF(M25>0,O25,"") | O25: =IF(K25="","",((K25*VLOOKUP(F25,Tabelle1!$A$2:$I$496,8,0))/$W$4)) | P25: =IF(K25="","",VLOOKUP(F25,Tabelle1!$A$2:$L$496,12,0))
B26: Krowa | C26: 28 | D26: =IF(K26="","",VLOOKUP(F26,Tabelle1!$A$2:$C$496,3,0)) | E26: =IF(K26="","",VLOOKUP(F26,Tabelle1!$A$2:$M$496,13,0)) | L26: =IF(K26="","",VLOOKUP(F26,Tabelle1!$A$2:$I$496,9,0)) | M26: =IF(K26="","",VLOOKUP(F26,Tabelle1!$A$2:$G$496,7,0)) | N26: =IF(M26>0,O26,"") | O26: =IF(K26="","",((K26*VLOOKUP(F26,Tabelle1!$A$2:$I$496,8,0))/$W$4)) | P26: =IF(K26="","",VLOOKUP(F26,Tabelle1!$A$2:$L$496,12,0))
B27: Krowa | C27: 29 | D27: =IF(K27="","",VLOOKUP(F27,Tabelle1!$A$2:$C$496,3,0)) | E27: =IF(K27="","",VLOOKUP(F27,Tabelle1!$A$2:$M$496,13,0)) | L27: =IF(K27="","",VLOOKUP(F27,Tabelle1!$A$2:$I$496,9,0)) | M27: =IF(K27="","",VLOOKUP(F27,Tabelle1!$A$2:$G$496,7,0)) | N27: =IF(M27>0,O27,"") | O27: =IF(K27="","",((K27*VLOOKUP(F27,Tabelle1!$A$2:$I$496,8,0))/$W$4)) | P27: =IF(K27="","",VLOOKUP(F27,Tabelle1!$A$2:$L$496,12,0))
B28: Krowa | C28: 30 | D28: =IF(K28="","",VLOOKUP(F28,Tabelle1!$A$2:$C$496,3,0)) | E28: =IF(K28="","",VLOOKUP(F28,Tabelle1!$A$2:$M$496,13,0)) | L28: =IF(K28="","",VLOOKUP(F28,Tabelle1!$A$2:$I$496,9,0)) | M28: =IF(K28="","",VLOOKUP(F28,Tabelle1!$A$2:$G$496,7,0)) | N28: =IF(M28>0,O28,"") | O28: =IF(K28="","",((K28*VLOOKUP(F28,Tabelle1!$A$2:$I$496,8,0))/$W$4)) | P28: =IF(K28="","",VLOOKUP(F28,Tabelle1!$A$2:$L$496,12,0))
B29: Krowa | C29: 31 | D29: =IF(K29="","",VLOOKUP(F29,Tabelle1!$A$2:$C$496,3,0)) | E29: =IF(K29="","",VLOOKUP(F29,Tabelle1!$A$2:$M$496,13,0)) | L29: =IF(K29="","",VLOOKUP(F29,Tabelle1!$A$2:$I$496,9,0)) | M29: =IF(K29="","",VLOOKUP(F29,Tabelle1!$A$2:$G$496,7,0)) | N29: =IF(M29>0,O29,"") | O29: =IF(K29="","",((K29*VLOOKUP(F29,Tabelle1!$A$2:$I$496,8,0))/$W$4)) | P29: =IF(K29="","",VLOOKUP(F29,Tabelle1!$A$2:$L$496,12,0))
B30: Krowa | C30: 32 | D30: =IF(K30="","",VLOOKUP(F30,Tabelle1!$A$2:$C$496,3,0)) | E30: =IF(K30="","",VLOOKUP(F30,Tabelle1!$A$2:$M$496,13,0)) | L30: =IF(K30="","",VLOOKUP(F30,Tabelle1!$A$2:$I$496,9,0)) | M30: =IF(K30="","",VLOOKUP(F30,Tabelle1!$A$2:$G$496,7,0)) | N30: =IF(M30>0,O30,"") | O30: =IF(K30="","",((K30*VLOOKUP(F30,Tabelle1!$A$2:$I$496,8,0))/$W$4)) | P30: =IF(K30="","",VLOOKUP(F30,Tabelle1!$A$2:$L$496,12,0))
B31: Krowa | C31: 33 | D31: =IF(K31="","",VLOOKUP(F31,Tabelle1!$A$2:$C$496,3,0)) | E31: =IF(K31="","",VLOOKUP(F31,Tabelle1!$A$2:$M$496,13,0)) | L31: =IF(K31="","",VLOOKUP(F31,Tabelle1!$A$2:$I$496,9,0)) | M31: =IF(K31="","",VLOOKUP(F31,Tabelle1!$A$2:$G$496,7,0)) | N31: =IF(M31>0,O31,"") | O31: =IF(K31="","",((K31*VLOOKUP(F31,Tabelle1!$A$2:$I$496,8,0))/$W$4)) | P31: =IF(K31="","",VLOOKUP(F31,Tabelle1!$A$2:$L$496,12,0))
B32: Krowa | C32: 34 | D32: =IF(K32="","",VLOOKUP(F32,Tabelle1!$A$2:$C$496,3,0)) | E32: =IF(K32="","",VLOOKUP(F32,Tabelle1!$A$2:$M$496,13,0)) | L32: =IF(K32="","",VLOOKUP(F32,Tabelle1!$A$2:$I$496,9,0)) | M32: =IF(K32="","",VLOOKUP(F32,Tabelle1!$A$2:$G$496,7,0)) | N32: =IF(M32>0,O32,"") | O32: =IF(K32="","",((K32*VLOOKUP(F32,Tabelle1!$A$2:$I$496,8,0))/$W$4)) | P32: =IF(K32="","",VLOOKUP(F32,Tabelle1!$A$2:$L$496,12,0))
... B41: Krowa | C41: 43 | D41: =IF(K41="","",VLOOKUP(F41,Tabelle1!$A$2:$C$496,3,0)) | E41: =IF(K41="","",VLOOKUP(F41,Tabelle1!$A$2:$M$496,13,0)) | L41: =IF(K41="","",VLOOKUP(F41,Tabelle1!$A$2:$I$496,9,0)) | M41: =IF(K41="","",VLOOKUP(F41,Tabelle1!$A$2:$G$496,7,0)) | N41: =IF(M41>0,O41,"") | O41: =IF(K41="","",((K41*VLOOKUP(F41,Tabelle1!$A$2:$I$496,8,0))/$W$4)) | P41: =IF(K41="","",VLOOKUP(F41,Tabelle1!$A$2:$L$496,12,0))
B42: Krowa | C42: 44 | D42: =IF(K42="","",VLOOKUP(F42,Tabelle1!$A$2:$C$496,3,0)) | E42: =IF(K42="","",VLOOKUP(F42,Tabelle1!$A$2:$M$496,13,0)) | L42: =IF(K42="","",VLOOKUP(F42,Tabelle1!$A$2:$I$496,9,0)) | M42: =IF(K42="","",VLOOKUP(F42,Tabelle1!$A$2:$G$496,7,0)) | N42: =IF(M42>0,O42,"") | O42: =IF(K42="","",((K42*VLOOKUP(F42,Tabelle1!$A$2:$I$496,8,0))/$W$4)) | P42: =IF(K42="","",VLOOKUP(F42,Tabelle1!$A$2:$L$496,12,0)) | R42: Waga zwierząt
B43: Krowa | C43: 45 | D43: =IF(K43="","",VLOOKUP(F43,Tabelle1!$A$2:$C$496,3,0)) | E43: =IF(K43="","",VLOOKUP(F43,Tabelle1!$A$2:$M$496,13,0)) | L43: =IF(K43="","",VLOOKUP(F43,Tabelle1!$A$2:$I$496,9,0)) | M43: =IF(K43="","",VLOOKUP(F43,Tabelle1!$A$2:$G$496,7,0)) | N43: =IF(M43>0,O43,"") | O43: =IF(K43="","",((K43*VLOOKUP(F43,Tabelle1!$A$2:$I$496,8,0))/$W$4)) | P43: =IF(K43="","",VLOOKUP(F43,Tabelle1!$A$2:$L$496,12,0))
B44: Krowa | C44: 46 | D44: =IF(K44="","",VLOOKUP(F44,Tabelle1!$A$2:$C$496,3,0)) | E44: =IF(K44="","",VLOOKUP(F44,Tabelle1!$A$2:$M$496,13,0)) | L44: =IF(K44="","",VLOOKUP(F44,Tabelle1!$A$2:$I$496,9,0)) | M44: =IF(K44="","",VLOOKUP(F44,Tabelle1!$A$2:$G$496,7,0)) | N44: =IF(M44>0,O44,"") | O44: =IF(K44="","",((K44*VLOOKUP(F44,Tabelle1!$A$2:$I$496,8,0))/$W$4)) | P44: =IF(K44="","",VLOOKUP(F44,Tabelle1!$A$2:$L$496,12,0)) | R44: Live weight unit | S44: Kilograms | U44: Total PCU
B45: Krowa | C45: 47 | D45: =IF(K45="","",VLOOKUP(F45,Tabelle1!$A$2:$C$496,3,0)) | E45: =IF(K45="","",VLOOKUP(F45,Tabelle1!$A$2:$M$496,13,0)) | L45: =IF(K45="","",VLOOKUP(F45,Tabelle1!$A$2:$I$496,9,0)) | M45: =IF(K45="","",VLOOKUP(F45,Tabelle1!$A$2:$G$496,7,0)) | N45: =IF(M45>0,O45,"") | O45: =IF(K45="","",((K45*VLOOKUP(F45,Tabelle1!$A$2:$I$496,8,0))/$W$4)) | P45: =IF(K45="","",VLOOKUP(F45,Tabelle1!$A$2:$L$496,12,0)) | S45: On-farm animals | U45: =(S47*T47)+(S48*T48)+(S49*T49)+(S50*T50)+(S51*T51)+(S52*T52) -> 0
B46: Krowa | C46: 48 | D46: =IF(K46="","",VLOOKUP(F46,Tabelle1!$A$2:$C$496,3,0)) | E46: =IF(K46="","",VLOOKUP(F46,Tabelle1!$A$2:$M$496,13,0)) | L46: =IF(K46="","",VLOOKUP(F46,Tabelle1!$A$2:$I$496,9,0)) | M46: =IF(K46="","",VLOOKUP(F46,Tabelle1!$A$2:$G$496,7,0)) | N46: =IF(M46>0,O46,"") | O46: =IF(K46="","",((K46*VLOOKUP(F46,Tabelle1!$A$2:$I$496,8,0))/$W$4)) | P46: =IF(K46="","",VLOOKUP(F46,Tabelle1!$A$2:$L$496,12,0)) | R46: Category | S46: Number | T46: Live weight
B47: Krowa | C47: 49 | D47: =IF(K47="","",VLOOKUP(F47,Tabelle1!$A$2:$C$496,3,0)) | E47: =IF(K47="","",VLOOKUP(F47,Tabelle1!$A$2:$M$496,13,0)) | L47: =IF(K47="","",VLOOKUP(F47,Tabelle1!$A$2:$I$496,9,0)) | M47: =IF(K47="","",VLOOKUP(F47,Tabelle1!$A$2:$G$496,7,0)) | N47: =IF(M47>0,O47,"") | O47: =IF(K47="","",((K47*VLOOKUP(F47,Tabelle1!$A$2:$I$496,8,0))/$W$4)) | P47: =IF(K47="","",VLOOKUP(F47,Tabelle1!$A$2:$L$496,12,0)) | R47: Dairy cows | S47: ='Karta informacyjna'!D8 -> 0 | T47: 425
B48: Krowa | C48: 50 | D48: =IF(K48="","",VLOOKUP(F48,Tabelle1!$A$2:$C$496,3,0)) | E48: =IF(K48="","",VLOOKUP(F48,Tabelle1!$A$2:$M$496,13,0)) | L48: =IF(K48="","",VLOOKUP(F48,Tabelle1!$A$2:$I$496,9,0)) | M48: =IF(K48="","",VLOOKUP(F48,Tabelle1!$A$2:$G$496,7,0)) | N48: =IF(M48>0,O48,"") | O48: =IF(K48="","",((K48*VLOOKUP(F48,Tabelle1!$A$2:$I$496,8,0))/$W$4)) | P48: =IF(K48="","",VLOOKUP(F48,Tabelle1!$A$2:$L$496,12,0)) | R48: Dry cows
...

Sheet Zasuszanie
A1: Zasuszanie
J2: =SUM(J4:J265) -> 0 | M2: =SUM(M4:M265) -> 0 | N2: =SUM(N4:N265) -> 0 | O2: =SUM(O4:O265) -> 0
A3: Data | B3: Kategoria bydła | C3: Liczba leczonych zwierząt | D3: Sposób podania (Route) | E3: Ryzyko powstawania oporności 1-6 | F3: Antybiotyk (Product) | G3: Dawka dzienna | H3: Ilość zastrzyków (liczba podań) | I3: Rozpoznanie (Treatments) | J3: Antybiogram [0=nie; 1=tak] | K3: Liczba tubostrzykawek (przez cały okres leczenia) (Amount used) | L3: Jednostka (Unit) | M3: Krytyczny [0=nie; 1=tak (Critical) [0 = no; 1 = yes] | N3: Antybiotyki krytyczne [mg/PCU] (Critically Important) [mg/PCU] | O3: Zużycie antybiotyków [mg/PCU] (Antibiotic Use) [mg/PCU] | P3: Klasa EMA A-D | T3: Total Antibiotic Use [mg/PCU] | U3: Total Critically Important [mg/PCU] | W3: Total PCU
D4: =IF(K4="","",VLOOKUP(F4,Tabelle1!$A$2:$C$496,3,0)) | E4: =IF(K4="","",VLOOKUP(F4,Tabelle1!$A$2:$M$496,13,0)) | L4: =IF(K4="","",VLOOKUP(F4,Tabelle1!$A$2:$I$496,9,0)) | M4: =IF(K4="","",VLOOKUP(F4,Tabelle1!$A$2:$G$496,7,0)) | N4: =IF(M4>0,O4,"") | O4: =IF(K4="","",((K4*VLOOKUP(F4,Tabelle1!$A$2:$I$496,8,0))/$W$4)) | P4: =IF(K4="","",VLOOKUP(F4,Tabelle1!$A$2:$L$496,12,0)) | R4: Total mg/PCU in herd | T4: =(SUM(O4:O265)) -> 0 | U4: =SUM(N4:N265) -> 0 | W4: =U45 -> 0
D5: =IF(K5="","",VLOOKUP(F5,Tabelle1!$A$2:$C$496,3,0)) | E5: =IF(K5="","",VLOOKUP(F5,Tabelle1!$A$2:$M$496,13,0)) | L5: =IF(K5="","",VLOOKUP(F5,Tabelle1!$A$2:$I$496,9,0)) | M5: =IF(K5="","",VLOOKUP(F5,Tabelle1!$A$2:$G$496,7,0)) | N5: =IF(M5>0,O5,"") | O5: =IF(K5="","",((K5*VLOOKUP(F5,Tabelle1!$A$2:$I$496,8,0))/$W$4)) | P5: =IF(K5="","",VLOOKUP(F5,Tabelle1!$A$2:$L$496,12,0))
D6: =IF(K6="","",VLOOKUP(F6,Tabelle1!$A$2:$C$496,3,0)) | E6: =IF(K6="","",VLOOKUP(F6,Tabelle1!$A$2:$M$496,13,0)) | L6: =IF(K6="","",VLOOKUP(F6,Tabelle1!$A$2:$I$496,9,0)) | M6: =IF(K6="","",VLOOKUP(F6,Tabelle1!$A$2:$G$496,7,0)) | N6: =IF(M6>0,O6,"") | O6: =IF(K6="","",((K6*VLOOKUP(F6,Tabelle1!$A$2:$I$496,8,0))/$W$4)) | P6: =IF(K6="","",VLOOKUP(F6,Tabelle1!$A$2:$L$496,12,0))
D7: =IF(K7="","",VLOOKUP(F7,Tabelle1!$A$2:$C$496,3,0)) | E7: =IF(K7="","",VLOOKUP(F7,Tabelle1!$A$2:$M$496,13,0)) | L7: =IF(K7="","",VLOOKUP(F7,Tabelle1!$A$2:$I$496,9,0)) | M7: =IF(K7="","",VLOOKUP(F7,Tabelle1!$A$2:$G$496,7,0)) | N7: =IF(M7>0,O7,"") | O7: =IF(K7="","",((K7*VLOOKUP(F7,Tabelle1!$A$2:$I$496,8,0))/$W$4)) | P7: =IF(K7="","",VLOOKUP(F7,Tabelle1!$A$2:$L$496,12,0)) | R7: Route | T7: Antibiotic Use [mg/PCU] | U7: Critically Important [mg/PCU]
D8: =IF(K8="","",VLOOKUP(F8,Tabelle1!$A$2:$C$496,3,0)) | E8: =IF(K8="","",VLOOKUP(F8,Tabelle1!$A$2:$M$496,13,0)) | L8: =IF(K8="","",VLOOKUP(F8,Tabelle1!$A$2:$I$496,9,0)) | M8: =IF(K8="","",VLOOKUP(F8,Tabelle1!$A$2:$G$496,7,0)) | N8: =IF(M8>0,O8,"") | O8: =IF(K8="","",((K8*VLOOKUP(F8,Tabelle1!$A$2:$I$496,8,0))/$W$4)) | P8: =IF(K8="","",VLOOKUP(F8,Tabelle1!$A$2:$L$496,12,0)) | R8: Injectable | T8: =SUMIFS($O$4:$O$265,$M$4:$M$265,"0",$D$4:$D$265,R8) -> 0 | U8: =SUMIFS($O$4:$O$265,$M$4:$M$265,"1",$D$4:$D$265,R8) -> 0
D9: =IF(K9="","",VLOOKUP(F9,Tabelle1!$A$2:$C$496,3,0)) | E9: =IF(K9="","",VLOOKUP(F9,Tabelle1!$A$2:$M$496,13,0)) | L9: =IF(K9="","",VLOOKUP(F9,Tabelle1!$A$2:$I$496,9,0)) | M9: =IF(K9="","",VLOOKUP(F9,Tabelle1!$A$2:$G$496,7,0)) | N9: =IF(M9>0,O9,"") | O9: =IF(K9="","",((K9*VLOOKUP(F9,Tabelle1!$A$2:$I$496,8,0))/$W$4)) | P9: =IF(K9="","",VLOOKUP(F9,Tabelle1!$A$2:$L$496,12,0)) | R9: Lactatingtube | T9: =SUMIFS($O$4:$O$265,$M$4:$M$265,"0",$D$4:$D$265,R9) -> 0 | U9: =SUMIFS($O$4:$O$265,$M$4:$M$265,"1",$D$4:$D$265,R9) -> 0
D10: =IF(K10="","",VLOOKUP(F10,Tabelle1!$A$2:$C$496,3,0)) | E10: =IF(K10="","",VLOOKUP(F10,Tabelle1!$A$2:$M$496,13,0)) | L10: =IF(K10="","",VLOOKUP(F10,Tabelle1!$A$2:$I$496,9,0)) | M10: =IF(K10="","",VLOOKUP(F10,Tabelle1!$A$2:$G$496,7,0)) | N10: =IF(M10>0,O10,"") | O10: =IF(K10="","",((K10*VLOOKUP(F10,Tabelle1!$A$2:$I$496,8,0))/$W$4)) | P10: =IF(K10="","",VLOOKUP(F10,Tabelle1!$A$2:$L$496,12,0)) | R10: Drytube | T10: =SUMIFS($O$4:$O$265,$M$4:$M$265,"0",$D$4:$D$265,R10) -> 0 | U10: =SUMIFS($O$4:$O$265,$M$4:$M$265,"1",$D$4:$D$265,R10) -> 0 | AD10: Błąd
D11: =IF(K11="","",VLOOKUP(F11,Tabelle1!$A$2:$C$496,3,0)) | E11: =IF(K11="","",VLOOKUP(F11,Tabelle1!$A$2:$M$496,13,0)) | L11: =IF(K11="","",VLOOKUP(F11,Tabelle1!$A$2:$I$496,9,0)) | M11: =IF(K11="","",VLOOKUP(F11,Tabelle1!$A$2:$G$496,7,0)) | N11: =IF(M11>0,O11,"") | O11: =IF(K11="","",((K11*VLOOKUP(F11,Tabelle1!$A$2:$I$496,8,0))/$W$4)) | P11: =IF(K11="","",VLOOKUP(F11,Tabelle1!$A$2:$L$496,12,0)) | R11: Other (IU, Oral, Pessary, Footbath) | T11: =SUM(T13:T16) -> 0 | U11: =SUM(U13:U16) -> 0 | AD11: Tylko zużyto krytyczne
D12: =IF(K12="","",VLOOKUP(F12,Tabelle1!$A$2:$C$496,3,0)) | E12: =IF(K12="","",VLOOKUP(F12,Tabelle1!$A$2:$M$496,13,0)) | L12: =IF(K12="","",VLOOKUP(F12,Tabelle1!$A$2:$I$496,9,0)) | M12: =IF(K12="","",VLOOKUP(F12,Tabelle1!$A$2:$G$496,7,0)) | N12: =IF(M12>0,O12,"") | O12: =IF(K12="","",((K12*VLOOKUP(F12,Tabelle1!$A$2:$I$496,8,0))/$W$4)) | P12: =IF(K12="","",VLOOKUP(F12,Tabelle1!$A$2:$L$496,12,0)) | R12: Total | T12: =SUM(T8:T11) -> 0 | U12: =SUM(U8:U11) -> 0 | V12: =T12+U12 -> 0
D13: =IF(K13="","",VLOOKUP(F13,Tabelle1!$A$2:$C$496,3,0)) | E13: =IF(K13="","",VLOOKUP(F13,Tabelle1!$A$2:$M$496,13,0)) | L13: =IF(K13="","",VLOOKUP(F13,Tabelle1!$A$2:$I$496,9,0)) | M13: =IF(K13="","",VLOOKUP(F13,Tabelle1!$A$2:$G$496,7,0)) | N13: =IF(M13>0,O13,"") | O13: =IF(K13="","",((K13*VLOOKUP(F13,Tabelle1!$A$2:$I$496,8,0))/$W$4)) | P13: =IF(K13="","",VLOOKUP(F13,Tabelle1!$A$2:$L$496,12,0)) | R13: Footbath | T13: =SUMIFS($O$4:$O$265,$M$4:$M$265,"0",$D$4:$D$265,R13) -> 0 | U13: =SUMIFS($O$4:$O$265,$M$4:$M$265,"1",$D$4:$D$265,R13) -> 0
D14: =IF(K14="","",VLOOKUP(F14,Tabelle1!$A$2:$C$496,3,0)) | E14: =IF(K14="","",VLOOKUP(F14,Tabelle1!$A$2:$M$496,13,0)) | L14: =IF(K14="","",VLOOKUP(F14,Tabelle1!$A$2:$I$496,9,0)) | M14: =IF(K14="","",VLOOKUP(F14,Tabelle1!$A$2:$G$496,7,0)) | N14: =IF(M14>0,O14,"") | O14: =IF(K14="","",((K14*VLOOKUP(F14,Tabelle1!$A$2:$I$496,8,0))/$W$4)) | P14: =IF(K14="","",VLOOKUP(F14,Tabelle1!$A$2:$L$496,12,0)) | R14: IU | T14: =SUMIFS($O$4:$O$265,$M$4:$M$265,"0",$D$4:$D$265,R14) -> 0 | U14: =SUMIFS($O$4:$O$265,$M$4:$M$265,"1",$D$4:$D$265,R14) -> 0
D15: =IF(K15="","",VLOOKUP(F15,Tabelle1!$A$2:$C$496,3,0)) | E15: =IF(K15="","",VLOOKUP(F15,Tabelle1!$A$2:$M$496,13,0)) | L15: =IF(K15="","",VLOOKUP(F15,Tabelle1!$A$2:$I$496,9,0)) | M15: =IF(K15="","",VLOOKUP(F15,Tabelle1!$A$2:$G$496,7,0)) | N15: =IF(M15>0,O15,"") | O15: =IF(K15="","",((K15*VLOOKUP(F15,Tabelle1!$A$2:$I$496,8,0))/$W$4)) | P15: =IF(K15="","",VLOOKUP(F15,Tabelle1!$A$2:$L$496,12,0)) | R15: Oral | T15: =SUMIFS($O$4:$O$265,$M$4:$M$265,"0",$D$4:$D$265,R15) -> 0 | U15: =SUMIFS($O$4:$O$265,$M$4:$M$265,"1",$D$4:$D$265,R15) -> 0
D16: =IF(K16="","",VLOOKUP(F16,Tabelle1!$A$2:$C$496,3,0)) | E16: =IF(K16="","",VLOOKUP(F16,Tabelle1!$A$2:$M$496,13,0)) | L16: =IF(K16="","",VLOOKUP(F16,Tabelle1!$A$2:$I$496,9,0)) | M16: =IF(K16="","",VLOOKUP(F16,Tabelle1!$A$2:$G$496,7,0)) | N16: =IF(M16>0,O16,"") | O16: =IF(K16="","",((K16*VLOOKUP(F16,Tabelle1!$A$2:$I$496,8,0))/$W$4)) | P16: =IF(K16="","",VLOOKUP(F16,Tabelle1!$A$2:$L$496,12,0)) | R16: Pessary | T16: =SUMIFS($O$4:$O$265,$M$4:$M$265,"0",$D$4:$D$265,R16) -> 0 | U16: =SUMIFS($O$4:$O$265,$M$4:$M$265,"1",$D$4:$D$265,R16) -> 0
D17: =IF(K17="","",VLOOKUP(F17,Tabelle1!$A$2:$C$496,3,0)) | E17: =IF(K17="","",VLOOKUP(F17,Tabelle1!$A$2:$M$496,13,0)) | L17: =IF(K17="","",VLOOKUP(F17,Tabelle1!$A$2:$I$496,9,0)) | M17: =IF(K17="","",VLOOKUP(F17,Tabelle1!$A$2:$G$496,7,0)) | N17: =IF(M17>0,O17,"") | O17: =IF(K17="","",((K17*VLOOKUP(F17,Tabelle1!$A$2:$I$496,8,0))/$W$4)) | P17: =IF(K17="","",VLOOKUP(F17,Tabelle1!$A$2:$L$496,12,0))
D18: =IF(K18="","",VLOOKUP(F18,Tabelle1!$A$2:$C$496,3,0)) | E18: =IF(K18="","",VLOOKUP(F18,Tabelle1!$A$2:$M$496,13,0)) | L18: =IF(K18="","",VLOOKUP(F18,Tabelle1!$A$2:$I$496,9,0)) | M18: =IF(K18="","",VLOOKUP(F18,Tabelle1!$A$2:$G$496,7,0)) | N18: =IF(M18>0,O18,"") | O18: =IF(K18="","",((K18*VLOOKUP(F18,Tabelle1!$A$2:$I$496,8,0))/$W$4)) | P18: =IF(K18="","",VLOOKUP(F18,Tabelle1!$A$2:$L$496,12,0))
D19: =IF(K19="","",VLOOKUP(F19,Tabelle1!$A$2:$C$496,3,0)) | E19: =IF(K19="","",VLOOKUP(F19,Tabelle1!$A$2:$M$496,13,0)) | L19: =IF(K19="","",VLOOKUP(F19,Tabelle1!$A$2:$I$496,9,0)) | M19: =IF(K19="","",VLOOKUP(F19,Tabelle1!$A$2:$G$496,7,0)) | N19: =IF(M19>0,O19,"") | O19: =IF(K19="","",((K19*VLOOKUP(F19,Tabelle1!$A$2:$I$496,8,0))/$W$4)) | P19: =IF(K19="","",VLOOKUP(F19,Tabelle1!$A$2:$L$496,12,0))
D20: =IF(K20="","",VLOOKUP(F20,Tabelle1!$A$2:$C$496,3,0)) | E20: =IF(K20="","",VLOOKUP(F20,Tabelle1!$A$2:$M$496,13,0)) | L20: =IF(K20="","",VLOOKUP(F20,Tabelle1!$A$2:$I$496,9,0)) | M20: =IF(K20="","",VLOOKUP(F20,Tabelle1!$A$2:$G$496,7,0)) | N20: =IF(M20>0,O20,"") | O20: =IF(K20="","",((K20*VLOOKUP(F20,Tabelle1!$A$2:$I$496,8,0))/$W$4)) | P20: =IF(K20="","",VLOOKUP(F20,Tabelle1!$A$2:$L$496,12,0)) | Q20: =SUM(O4:O6) -> 0
D21: =IF(K21="","",VLOOKUP(F21,Tabelle1!$A$2:$C$496,3,0)) | E21: =IF(K21="","",VLOOKUP(F21,Tabelle1!$A$2:$M$496,13,0)) | L21: =IF(K21="","",VLOOKUP(F21,Tabelle1!$A$2:$I$496,9,0)) | M21: =IF(K21="","",VLOOKUP(F21,Tabelle1!$A$2:$G$496,7,0)) | N21: =IF(M21>0,O21,"") | O21: =IF(K21="","",((K21*VLOOKUP(F21,Tabelle1!$A$2:$I$496,8,0))/$W$4)) | P21: =IF(K21="","",VLOOKUP(F21,Tabelle1!$A$2:$L$496,12,0))
D22: =IF(K22="","",VLOOKUP(F22,Tabelle1!$A$2:$C$496,3,0)) | E22: =IF(K22="","",VLOOKUP(F22,Tabelle1!$A$2:$M$496,13,0)) | L22: =IF(K22="","",VLOOKUP(F22,Tabelle1!$A$2:$I$496,9,0)) | M22: =IF(K22="","",VLOOKUP(F22,Tabelle1!$A$2:$G$496,7,0)) | N22: =IF(M22>0,O22,"") | O22: =IF(K22="","",((K22*VLOOKUP(F22,Tabelle1!$A$2:$I$496,8,0))/$W$4)) | P22: =IF(K22="","",VLOOKUP(F22,Tabelle1!$A$2:$L$496,12,0))
D23: =IF(K23="","",VLOOKUP(F23,Tabelle1!$A$2:$C$496,3,0)) | E23: =IF(K23="","",VLOOKUP(F23,Tabelle1!$A$2:$M$496,13,0)) | L23: =IF(K23="","",VLOOKUP(F23,Tabelle1!$A$2:$I$496,9,0)) | M23: =IF(K23="","",VLOOKUP(F23,Tabelle1!$A$2:$G$496,7,0)) | N23: =IF(M23>0,O23,"") | O23: =IF(K23="","",((K23*VLOOKUP(F23,Tabelle1!$A$2:$I$496,8,0))/$W$4)) | P23: =IF(K23="","",VLOOKUP(F23,Tabelle1!$A$2:$L$496,12,0))
D24: =IF(K24="","",VLOOKUP(F24,Tabelle1!$A$2:$C$496,3,0)) | E24: =IF(K24="","",VLOOKUP(F24,Tabelle1!$A$2:$M$496,13,0)) | L24: =IF(K24="","",VLOOKUP(F24,Tabelle1!$A$2:$I$496,9,0)) | M24: =IF(K24="","",VLOOKUP(F24,Tabelle1!$A$2:$G$496,7,0)) | N24: =IF(M24>0,O24,"") | O24: =IF(K24="","",((K24*VLOOKUP(F24,Tabelle1!$A$2:$I$496,8,0))/$W$4)) | P24: =IF(K24="","",VLOOKUP(F24,Tabelle1!$A$2:$L$496,12,0))
D25: =IF(K25="","",VLOOKUP(F25,Tabelle1!$A$2:$C$496,3,0)) | E25: =IF(K25="","",VLOOKUP(F25,Tabelle1!$A$2:$M$496,13,0)) | L25: =IF(K25="","",VLOOKUP(F25,Tabelle1!$A$2:$I$496,9,0)) | M25: =IF(K25="","",VLOOKUP(F25,Tabelle1!$A$2:$G$496,7,0)) | N25: =IF(M25>0,O25,"") | O25: =IF(K25="","",((K25*VLOOKUP(F25,Tabelle1!$A$2:$I$496,8,0))/$W$4)) | P25: =IF(K25="","",VLOOKUP(F25,Tabelle1!$A$2:$L$496,12,0))
D26: =IF(K26="","",VLOOKUP(F26,Tabelle1!$A$2:$C$496,3,0)) | E26: =IF(K26="","",VLOOKUP(F26,Tabelle1!$A$2:$M$496,13,0)) | L26: =IF(K26="","",VLOOKUP(F26,Tabelle1!$A$2:$I$496,9,0)) | M26: =IF(K26="","",VLOOKUP(F26,Tabelle1!$A$2:$G$496,7,0)) | N26: =IF(M26>0,O26,"") | O26: =IF(K26="","",((K26*VLOOKUP(F26,Tabelle1!$A$2:$I$496,8,0))/$W$4)) | P26: =IF(K26="","",VLOOKUP(F26,Tabelle1!$A$2:$L$496,12,0))
D27: =IF(K27="","",VLOOKUP(F27,Tabelle1!$A$2:$C$496,3,0)) | E27: =IF(K27="","",VLOOKUP(F27,Tabelle1!$A$2:$M$496,13,0)) | L27: =IF(K27="","",VLOOKUP(F27,Tabelle1!$A$2:$I$496,9,0)) | M27: =IF(K27="","",VLOOKUP(F27,Tabelle1!$A$2:$G$496,7,0)) | N27: =IF(M27>0,O27,"") | O27: =IF(K27="","",((K27*VLOOKUP(F27,Tabelle1!$A$2:$I$496,8,0))/$W$4)) | P27: =IF(K27="","",VLOOKUP(F27,Tabelle1!$A$2:$L$496,12,0))
D28: =IF(K28="","",VLOOKUP(F28,Tabelle1!$A$2:$C$496,3,0)) | E28: =IF(K28="","",VLOOKUP(F28,Tabelle1!$A$2:$M$496,13,0)) | L28: =IF(K28="","",VLOOKUP(F28,Tabelle1!$A$2:$I$496,9,0)) | M28: =IF(K28="","",VLOOKUP(F28,Tabelle1!$A$2:$G$496,7,0)) | N28: =IF(M28>0,O28,"") | O28: =IF(K28="","",((K28*VLOOKUP(F28,Tabelle1!$A$2:$I$496,8,0))/$W$4)) | P28: =IF(K28="","",VLOOKUP(F28,Tabelle1!$A$2:$L$496,12,0))
D29: =IF(K29="","",VLOOKUP(F29,Tabelle1!$A$2:$C$496,3,0)) | E29: =IF(K29="","",VLOOKUP(F29,Tabelle1!$A$2:$M$496,13,0)) | L29: =IF(K29="","",VLOOKUP(F29,Tabelle1!$A$2:$I$496,9,0)) | M29: =IF(K29="","",VLOOKUP(F29,Tabelle1!$A$2:$G$496,7,0)) | N29: =IF(M29>0,O29,"") | O29: =IF(K29="","",((K29*VLOOKUP(F29,Tabelle1!$A$2:$I$496,8,0))/$W$4)) | P29: =IF(K29="","",VLOOKUP(F29,Tabelle1!$A$2:$L$496,12,0))
D30: =IF(K30="","",VLOOKUP(F30,Tabelle1!$A$2:$C$496,3,0)) | E30: =IF(K30="","",VLOOKUP(F30,Tabelle1!$A$2:$M$496,13,0)) | L30: =IF(K30="","",VLOOKUP(F30,Tabelle1!$A$2:$I$496,9,0)) | M30: =IF(K30="","",VLOOKUP(F30,Tabelle1!$A$2:$G$496,7,0)) | N30: =IF(M30>0,O30,"") | O30: =IF(K30="","",((K30*VLOOKUP(F30,Tabelle1!$A$2:$I$496,8,0))/$W$4)) | P30: =IF(K30="","",VLOOKUP(F30,Tabelle1!$A$2:$L$496,12,0))
D31: =IF(K31="","",VLOOKUP(F31,Tabelle1!$A$2:$C$496,3,0)) | E31: =IF(K31="","",VLOOKUP(F31,Tabelle1!$A$2:$M$496,13,0)) | L31: =IF(K31="","",VLOOKUP(F31,Tabelle1!$A$2:$I$496,9,0)) | M31: =IF(K31="","",VLOOKUP(F31,Tabelle1!$A$2:$G$496,7,0)) | N31: =IF(M31>0,O31,"") | O31: =IF(K31="","",((K31*VLOOKUP(F31,Tabelle1!$A$2:$I$496,8,0))/$W$4)) | P31: =IF(K31="","",VLOOKUP(F31,Tabelle1!$A$2:$L$496,12,0))
D32: =IF(K32="","",VLOOKUP(F32,Tabelle1!$A$2:$C$496,3,0)) | E32: =IF(K32="","",VLOOKUP(F32,Tabelle1!$A$2:$M$496,13,0)) | L32: =IF(K32="","",VLOOKUP(F32,Tabelle1!$A$2:$I$496,9,0)) | M32: =IF(K32="","",VLOOKUP(F32,Tabelle1!$A$2:$G$496,7,0)) | N32: =IF(M32>0,O32,"") | O32: =IF(K32="","",((K32*VLOOKUP(F32,Tabelle1!$A$2:$I$496,8,0))/$W$4)) | P32: =IF(K32="","",VLOOKUP(F32,Tabelle1!$A$2:$L$496,12,0))
... D41: =IF(K41="","",VLOOKUP(F41,Tabelle1!$A$2:$C$496,3,0)) | E41: =IF(K41="","",VLOOKUP(F41,Tabelle1!$A$2:$M$496,13,0)) | L41: =IF(K41="","",VLOOKUP(F41,Tabelle1!$A$2:$I$496,9,0)) | M41: =IF(K41="","",VLOOKUP(F41,Tabelle1!$A$2:$G$496,7,0)) | N41: =IF(M41>0,O41,"") | O41: =IF(K41="","",((K41*VLOOKUP(F41,Tabelle1!$A$2:$I$496,8,0))/$W$4)) | P41: =IF(K41="","",VLOOKUP(F41,Tabelle1!$A$2:$L$496,12,0))
D42: =IF(K42="","",VLOOKUP(F42,Tabelle1!$A$2:$C$496,3,0)) | E42: =IF(K42="","",VLOOKUP(F42,Tabelle1!$A$2:$M$496,13,0)) | L42: =IF(K42="","",VLOOKUP(F42,Tabelle1!$A$2:$I$496,9,0)) | M42: =IF(K42="","",VLOOKUP(F42,Tabelle1!$A$2:$G$496,7,0)) | N42: =IF(M42>0,O42,"") | O42: =IF(K42="","",((K42*VLOOKUP(F42,Tabelle1!$A$2:$I$496,8,0))/$W$4)) | P42: =IF(K42="","",VLOOKUP(F42,Tabelle1!$A$2:$L$496,12,0)) | R42: Waga zwierząt
D43: =IF(K43="","",VLOOKUP(F43,Tabelle1!$A$2:$C$496,3,0)) | E43: =IF(K43="","",VLOOKUP(F43,Tabelle1!$A$2:$M$496,13,0)) | L43: =IF(K43="","",VLOOKUP(F43,Tabelle1!$A$2:$I$496,9,0)) | M43: =IF(K43="","",VLOOKUP(F43,Tabelle1!$A$2:$G$496,7,0)) | N43: =IF(M43>0,O43,"") | O43: =IF(K43="","",((K43*VLOOKUP(F43,Tabelle1!$A$2:$I$496,8,0))/$W$4)) | P43: =IF(K43="","",VLOOKUP(F43,Tabelle1!$A$2:$L$496,12,0))
D44: =IF(K44="","",VLOOKUP(F44,Tabelle1!$A$2:$C$496,3,0)) | E44: =IF(K44="","",VLOOKUP(F44,Tabelle1!$A$2:$M$496,13,0)) | L44: =IF(K44="","",VLOOKUP(F44,Tabelle1!$A$2:$I$496,9,0)) | M44: =IF(K44="","",VLOOKUP(F44,Tabelle1!$A$2:$G$496,7,0)) | N44: =IF(M44>0,O44,"") | O44: =IF(K44="","",((K44*VLOOKUP(F44,Tabelle1!$A$2:$I$496,8,0))/$W$4)) | P44: =IF(K44="","",VLOOKUP(F44,Tabelle1!$A$2:$L$496,12,0)) | R44: Live weight unit | S44: Kilograms | U44: Total PCU
D45: =IF(K45="","",VLOOKUP(F45,Tabelle1!$A$2:$C$496,3,0)) | E45: =IF(K45="","",VLOOKUP(F45,Tabelle1!$A$2:$M$496,13,0)) | L45: =IF(K45="","",VLOOKUP(F45,Tabelle1!$A$2:$I$496,9,0)) | M45: =IF(K45="","",VLOOKUP(F45,Tabelle1!$A$2:$G$496,7,0)) | N45: =IF(M45>0,O45,"") | O45: =IF(K45="","",((K45*VLOOKUP(F45,Tabelle1!$A$2:$I$496,8,0))/$W$4)) | P45: =IF(K45="","",VLOOKUP(F45,Tabelle1!$A$2:$L$496,12,0)) | S45: On-farm animals | U45: =(S47*T47)+(S48*T48)+(S49*T49)+(S50*T50)+(S51*T51)+(S52*T52) -> 0
D46: =IF(K46="","",VLOOKUP(F46,Tabelle1!$A$2:$C$496,3,0)) | E46: =IF(K46="","",VLOOKUP(F46,Tabelle1!$A$2:$M$496,13,0)) | L46: =IF(K46="","",VLOOKUP(F46,Tabelle1!$A$2:$I$496,9,0)) | M46: =IF(K46="","",VLOOKUP(F46,Tabelle1!$A$2:$G$496,7,0)) | N46: =IF(M46>0,O46,"") | O46: =IF(K46="","",((K46*VLOOKUP(F46,Tabelle1!$A$2:$I$496,8,0))/$W$4)) | P46: =IF(K46="","",VLOOKUP(F46,Tabelle1!$A$2:$L$496,12,0)) | R46: Category | S46: Number | T46: Live weight
D47: =IF(K47="","",VLOOKUP(F47,Tabelle1!$A$2:$C$496,3,0)) | E47: =IF(K47="","",VLOOKUP(F47,Tabelle1!$A$2:$M$496,13,0)) | L47: =IF(K47="","",VLOOKUP(F47,Tabelle1!$A$2:$I$496,9,0)) | M47: =IF(K47="","",VLOOKUP(F47,Tabelle1!$A$2:$G$496,7,0)) | N47: =IF(M47>0,O47,"") | O47: =IF(K47="","",((K47*VLOOKUP(F47,Tabelle1!$A$2:$I$496,8,0))/$W$4)) | P47: =IF(K47="","",VLOOKUP(F47,Tabelle1!$A$2:$L$496,12,0)) | R47: Dairy cows | S47: ='Karta informacyjna'!D8 -> 0 | T47: 425
D48: =IF(K48="","",VLOOKUP(F48,Tabelle1!$A$2:$C$496,3,0)) | E48: =IF(K48="","",VLOOKUP(F48,Tabelle1!$A$2:$M$496,13,0)) | L48: =IF(K48="","",VLOOKUP(F48,Tabelle1!$A$2:$I$496,9,0)) | M48: =IF(K48="","",VLOOKUP(F48,Tabelle1!$A$2:$G$496,7,0)) | N48: =IF(M48>0,O48,"") | O48: =IF(K48="","",((K48*VLOOKUP(F48,Tabelle1!$A$2:$I$496,8,0))/$W$4)) | P48: =IF(K48="","",VLOOKUP(F48,Tabelle1!$A$2:$L$496,12,0)) | R48: Dry cows
...

Sheet Podsumowanie
B1: Zużycie razem (mg/PCU) | C1: Zużucie krytycznych (mg/PCU) | D1: Krytyczne (szt.) | E1: Krytyczne (%)
A2: Leczenie ogólne | B2: ='Leczenie ogólne'!T4 -> 0 | C2: ='Leczenie ogólne'!U4 -> 0 | D2: ='Leczenie ogólne'!M2 -> 0
A3: Mastitis | B3: =Mastitis!T4 -> 0 | C3: =Mastitis!U4 -> 0 | D3: =Mastitis!M2 -> 0
A4: Zasuszanie | B4: =Zasuszanie!T4 -> 0 | C4: =Zasuszanie!U4 -> 0 | D4: =Zasuszanie!M2 -> 0
A5: Razem | B5: =SUM(B2:B4) -> 0 | C5: =SUM(C2:C4) -> 0 | D5: =SUM(D2:D4) -> 0

Sheet Tabelle1
A1: Drug / Medikament | B1: Active | C1: Route / Verabreichungsweg | D1: Dose mg/kg (or mg/tube) | E1: Treatments (days/Tubes) | F1: Dose per Tx [=D] | G1: Critical [0 = no; 1 = yes] | H1: mg/unit | I1: Units | J1: DDD | K1: DCD | L1: Klasa EMA | M1: Kategorie ryzyka | S1: Route / Verabreichungsweg | V1: Einheit | W1: DDD | X1: DCD | AA1: Units | AC1: Weight (Kg) | AF1: Droga Podawania
A2: Advocin 180 mg/ml Solution for Injection for Cattle | B2: Danofloxacin Mesylate | C2: Injectable | D2: 6 | E2: 4 | F2: =D2*$AC$2 -> 2550 | G2: 1 | H2: 180 | I2: ml | J2: 1.9 | K2: 5.1 | L2: D | S2: Zastrzyk/ iniekcja | T2: Injizierbar | U2: Injizierbar | V2: ml | W2: ? | X2: ? | AA2: ml | AC2: 425 | AD2: Dairy cow | AF2: 1 | AG2: Indywidualne leczenie miejscowe (np. podanie dowymieniowe, krople do oczu lub uszu)
A3: Advocin 2.5% Solution for Injection | B3: Danofloxacin Mesylate | C3: Injectable | D3: 1.25 | E3: 3 | F3: =D3*$AC$2 -> 531.25 | G3: 1 | H3: 25 | I3: ml | J3: 1.9 | K3: 5.1 | L3: B | S3: Tubostrzykawka | T3: Intrammamärer Tuben bei der Laktation | U3: IMM | V3: Tubes | W3: 1 | X3: 3 | AA3: grams | AC3: 425 | AD3: Slaughtered Cow | AF3: 2 | AG3: Indywidualne leczenie pozajelitowe (dożylnie, domięśniowo, podskórnie)
A4: Alamycin 100mg/ml Solution for Injection | B4: v | C4: Injectable | D4: 4 | E4: 3 | F4: =D4*$AC$2 -> 1700 | G4: 0 | H4: 100 | I4: ml | J4: 6.5 | K4: 23 | S4: Kąpiel racic | T4: Intrammamärer Tuben für trockene Kühe | U4: DCT | V4: Tubes | X4: 4 | AA4: Tubes | AC4: 200 | AD4: Slaughtered Heifer | AF4: 3 | AG4: Indywidualne leczenie doustne (tabletki, bolus doustny)
A5: Alamycin LA 200mg/ml Solution for Injection | B5: Oxytetracycline | C5: Injectable | D5: 20 | E5: 1 | F5: =D5*$AC$2 -> 8500 | G5: 0 | H5: 200 | I5: ml | J5: 6.5 | K5: 23 | S5: Domacicznie | T5: Fußbad | U5: Fußbad | V5: grams | W5: =mg/unit | X5: =mg/unit | AA5: Units | AC5: 425 | AD5: Slaughtered Bullocks and Bulls | AF5: 4 | AG5: Pozajelitowe stosowanie antybiotyków w stadach (metafilaksja), tylko jeśli jest odpowiednio uzasadnione
A6: Alamycin LA 300 Solution for Injection 300mg/ml | B6: Oxytetracycline | C6: Injectable | D6: 20 | E6: 1 | F6: =D6*$AC$2 -> 8500 | G6: 0 | H6: 300 | I6: ml | J6: 6.5 | K6: 23 | S6: Doustnie | T6: Sonstiges | U6: Orale Produkte & Intrauterine Lösungen | AC6: 140 | AD6: Slaughtered Calves and Young Cattle | AF6: 5 | AG6: Doustne stosowanie antybiotyków w stadach wodzie do picia / z preparatem mlekozastępczym (metafilaksja), tylko jeśli są odpowiednio uzasadnione przypadki
A7: Amfipen LA 100 mg/ml suspension for injection | B7: Ampicillin | C7: Injectable | D7: 15 | E7: 2 | F7: =D7*$AC$2 -> 6375 | G7: 0 | H7: 100 | I7: ml | J7: 8.3 | K7: 29 | S7: Inny | V7: Units | W7: 1 | X7: 2 | AF7: 6 | AG7: Doustne stosowane antybiotyków w stadach w postaci paszy lub premiksów (metafilaksja), tylko w owiednio uzasadnionym przypadku
A8: Amoxan 70 | B8: Amoxicillin | C8: Oral | D8: 21 | E8: 5 | F8: =D8*$AC$6 -> 2940 | G8: 0 | H8: 70 | I8: grams | M8: https://www.vetpharm.uzh.ch/tak/05000000/00052148.01 | V8: ml or mg | W8: ? | X8: ?
A9: Amoxypen Injection 150 mg/ml Suspension for injection | B9: Amoxicillin Trihydrate | C9: Injectable | D9: 7 | E9: 5 | F9: =D9*$AC$2 -> 2975 | G9: 0 | H9: 150 | I9: ml | J9: 8.3 | K9: 29 | V9: Units | W9: ? | X9: ?
A10: Amoxypen LA 150 mg/ml Suspension for injection | B10: Amoxicillin Trihydrate | C10: Injectable | D10: 15 | E10: 2 | F10: =D10*$AC$2 -> 6375 | G10: 0 | H10: 150 | I10: ml | J10: 8.3 | K10: 29
A11: Apotil 300 mg/ml Solution for Injection | B11: Tilmicosin | C11: Injectable | D11: 10 | E11: 1 | F11: =D11*$AC$2 -> 4250 | G11: 0 | H11: 300 | I11: ml | J11: 4 | K11: 9.8
A12: Apralan Soluble Powder for Oral Solution | B12: Apramycin Sulfate | C12: Oral | D12: 40 | E12: 5 | F12: 5600 | G12: 0 | H12: 1000 | I12: grams | J12: 30 | K12: 150
A13: Baycox Multi 50 mg/ml Suspension | B13: Toltrazuril | C13: Oral | D13: 50 | E13: 1 | F13: =D13 -> 50 | G13: 0 | H13: =F13 -> 50 | I13: ml
A14: Bayofly - No Antibiotic | M14: https://tiergesundheit.bayer.de/omr/online/2786.pdf
A15: Baytril 100 mg/ml | B15: Enrofloxacin | C15: Injectable | D15: 5 | E15: 5 | F15: =D15*$AC$2 -> 2125 | G15: 1 | H15: 100 | I15: ml | J15: 4.2 | K15: 16
A16: Baytril 2.5% Oral Solution | B16: Enrofloxacin | C16: Oral | D16: 2.5 | E16: 3 | F16: 350 | G16: 1 | H16: 25 | I16: ml | J16: 4.7 | K16: 22
A17: Baytril 50 mg/ml | B17: Enrofloxacin | C17: Injectable | D17: 5 | E17: 5 | F17: =D17*$AC$2 -> 2125 | G17: 1 | H17: 50 | I17: ml | J17: 4.2 | K17: 16
A18: Baytril Max 100 mg/ml | B18: Enrofloxacin | C18: Injectable | D18: 7.5 | E18: 1 | F18: =D18*$AC$2 -> 3187.5 | G18: 1 | H18: 100 | I18: ml | J18: 4.2 | K18: 16
A19: Benestermycin | B19: Benzylpenicillin Penicilline | C19: Drytube | D19: 280 | E19: 1 | F19: =D19 -> 280 | G19: 0 | H19: 100 | I19: Tubes | M19: https://medikamio.com/de-at/medikamente/benestermycin-suspension-zur-intramammaren-anwendung-fur-rinder/pil
